Workbook

Sheet EV1
A1: JANELA_EV1 | B1: DATA_EV1 | C1: R_SPX | D1: R_SHY | E1: R_BTC | F1: R_ETH | G1: R_OURO | H1: R_PRATA | I1: R_DXY
A2: ESTIMAÇÃO | B2: 2019/09/27 | C2: -0.0053204153 | D2: 0.00058993571 | E2: 0.01623388 | F2: 0.046774649 | G2: -0.005901294 | H2: -0.014469346 | I2: -0.0002320408
A3: ESTIMAÇÃO | B3: 2019/09/30 | C3: 0.0050181127 | D3: 0.00047169812 | E3: 0.005079536 | F3: 0.029113467 | G3: -0.016631182 | H3: -0.031809928 | I3: 0.002700444
A4: ESTIMAÇÃO | B4: 2019/10/01 | C4: -0.012337698 | D4: -0.00047169812 | E4: 0.0059396114 | F4: -0.014175447 | G4: 0.0045608181 | H4: 0.014023017 | I4: -0.0025087542
A5: ESTIMAÇÃO | B5: 2019/10/02 | C5: -0.018051899 | D5: 0.0010610081 | E5: 0.0059469603 | F5: 0.018825178 | G5: 0.013785727 | H5: 0.01839661 | I5: -0.0011001934
A6: ESTIMAÇÃO | B6: 2019/10/03 | C6: 0.0079335382 | D6: 0.0021186449 | E6: -0.015979371 | F6: -0.030971918 | G6: 0.0036545101 | H6: 0 | I6: -0.0015665826
A7: ESTIMAÇÃO | B7: 2019/10/04 | C7: 0.014123661 | D7: -0.00011758481 | E7: -0.0065654266 | F7: 0.010140602 | G7: -0.00026581606 | H7: -0.00028485971 | I7: -0.00056659518
A8: ESTIMAÇÃO | B8: 2019/10/07 | C8: -0.004481572 | D8: -0.0010588859 | E8: 0.0048243162 | F8: 0.023460946 | G8: -0.0073377689 | H8: -0.0065742698 | I8: 0.0016078881
A9: ESTIMAÇÃO | B9: 2019/10/08 | C9: -0.015672743 | D9: 0.00058840837 | E9: -0.0020443573 | F9: 0.0045991949 | G9: 0.007942398 | H9: 0.015649772 | I9: 0.0016759216
A10: ESTIMAÇÃO | B10: 2019/10/09 | C10: 0.0090495241 | D10: -0.00058840837 | E10: 0.043628562 | F10: 0.060083344 | G10: 0.00012619512 | H10: -0.00056481221 | I10: -0.00015132332
A11: ESTIMAÇÃO | B11: 2019/10/10 | C11: 0.0063849982 | D11: -0.0011778564 | E11: -0.0010786029 | F11: -0.0084872471 | G11: -0.0076000366 | H11: -0.012507269 | I11: -0.0042159815
A12: ESTIMAÇÃO | B12: 2019/10/11 | C12: 0.010899844 | D12: -0.00094328506 | E12: -0.031314732 | F12: -0.048589286 | G12: -0.002982426 | H12: 0.0034266167 | I12: -0.0040608781
A13: ESTIMAÇÃO | B13: 2019/10/14 | C13: -0.0013812855 | D13: 0.0001179593 | E13: 0.006340262 | F13: 0.023767565 | G13: 0.0020450933 | H13: 0.0062517964 | I13: 0.001555234
... A125: AJUSTE | B125: 2020/03/25 | C125: 0.011497415 | D125: 0.0011558023 | E125: -0.0080115496 | F125: -0.018661997 | G125: -0.0050930013 | H125: 0.011149941 | I125: -0.0097396493

Sheet EV2
A1: JANELA_EV2 | B1: DATA_EV2 | C1: R_SPX | D1: R_SHY | E1: R_BTC | F1: R_ETH | G1: R_OURO | H1: R_PRATA | I1: R_DXY
A2: ESTIMAÇÃO | B2: 2021/09/13 | C2: 0.0022627232 | D2: 0.00023196474 | E2: 0.0017621637 | F2: 0.022782492 | G2: 0.0034349612 | H2: -8.4329475e-05 | I2: 0.0010040107
A3: ESTIMAÇÃO | B3: 2021/09/14 | C3: -0.0057452076 | D3: 0.0001159622 | E3: 0.046272077 | F3: 0.042795715 | G3: 0.0059926356 | H3: 0.0049633112 | I3: -0.0005612581
A4: ESTIMAÇÃO | B4: 2021/09/15 | C4: 0.0084269532 | D4: 0 | E4: 0.02275454 | F4: 0.052851888 | G4: -0.0064945764 | H4: -0.00058758107 | I4: -0.0008100621
A5: ESTIMAÇÃO | B5: 2021/09/16 | C5: -0.0015411249 | D5: -0.00034792694 | E5: -0.0081907461 | F5: -0.012241774 | G5: -0.022110444 | H5: -0.038058476 | I5: 0.0041406141
A6: ESTIMAÇÃO | B6: 2021/09/17 | C6: -0.0091616036 | D6: -0.00023201856 | E6: -0.010854036 | F6: -0.049582689 | G6: 0.00043905291 | H6: -0.023720016 | I6: 0.0028260293
A7: ESTIMAÇÃO | B7: 2021/09/20 | C7: -0.017132161 | D7: 0.00023201856 | E7: -0.098262379 | F7: -0.13849639 | G7: 0.0055258182 | H7: -0.0066088171 | I7: 0.00086876785
A8: ESTIMAÇÃO | B8: 2021/09/21 | C8: -0.00080349871 | D8: 0.00023196474 | E8: -0.051488272 | F8: -0.068014304 | G8: 0.0058618704 | H8: 0.010130575 | I8: -0.00077220081
A9: ESTIMAÇÃO | B9: 2021/09/22 | C9: 0.0094631441 | D9: -0.00058001278 | E9: 0.068399605 | F9: 0.10740227 | G9: -0.0035797405 | H9: 0.0087725691 | I9: 0.0027642973
A10: ESTIMAÇÃO | B10: 2021/09/23 | C10: 0.012075311 | D10: -0.00058034939 | E10: 0.029856248 | F10: 0.02491734 | G10: -0.014437023 | H10: -0.0080785972 | I10: -0.0046006676
A11: ESTIMAÇÃO | B11: 2021/09/24 | C11: 0.0014599362 | D11: -0.00034837137 | E11: -0.046862132 | F11: -0.073582524 | G11: 0.0041747497 | H11: -0.0032114339 | I11: 0.0031551861
A12: ESTIMAÇÃO | B12: 2021/09/27 | C12: -0.0027869571 | D12: -0.00011615076 | E12: -0.01419986 | F12: 0.0008420261 | G12: -5.7147592e-06 | H12: 0.010429474 | I12: 0.00059986076
A13: ESTIMAÇÃO | B13: 2021/09/28 | C13: -0.020578963 | D13: 0.00011615076 | E13: -0.028852324 | F13: -0.044191979 | G13: -0.0092837531 | H13: -0.0096267629 | I13: 0.0040930011
... A126: AJUSTE | B126: 2022/03/10 | C126: -0.0043010819 | D126: -0.00083100854 | E126: -0.0625469 | F126: -0.045620064 | G126: 0.0021919329 | H126: 0.0057658488 | I126: 0.0054867169

Sheet EV1-ER-AR
A1: JANELA_EV1 | B1: DATA_EV1 | C1: R_SPX | D1: LAG1_SPX | E1: LAG2_SPX | F1: LAG3_SPX | G1: LAG4_SPX | H1: R_SPX_ESPERADO_EV1 | I1: AR_SPX_EV1 | K1: JANELA_EV1 | L1: DATA_EV1 | M1: R_SHY | N1: LAG1_SHY | O1: LAG2_SHY | P1: LAG3_SHY | Q1: LAG4_SHY | R1: LAG5_SHY | S1: R_SHY_ESPERADO_EV1 | T1: AR_SHY_EV1 | V1: JANELA_EV1 | W1: DATA_EV1 | X1: R_BTC | Y1: LAG1_BTC | Z1: LAG2_BTC | AA1: R_BTC_ESPERADO_EV1 | AB1: AR_BTC_EV1 | AD1: JANELA_EV1 | AE1: DATA_EV1 | AF1: R_ETH | AG1: R_ETH_ESPERADO_EV1 | AH1: AR_ETH_EV1 | AJ1: JANELA_EV1 | AK1: DATA_EV1 | AL1: R_OURO | AM1: LAG1_OURO | AN1: LAG2_OURO | AO1: LAG3_OURO | AP1: LAG4_OURO | AQ1: R_OURO_ESPERADO_EV1 | AR1: AR_OURO_EV1 | AT1: JANELA_EV1 | AU1: DATA_EV1 | AV1: R_PRATA | AW1: LAG1_PRATA | AX1: LAG2_PRATA | AY1: R_PRATA_ESPERADO_EV1 | AZ1: AR_PRATA_EV1 | BB1: JANELA_EV1 | BC1: DATA_EV1 | BD1: R_DXY | BE1: LAG1_DXY | BF1: R_DXY_ESPERADO_EV1 | BG1: AR_DXY_EV1
A2: ESTIMAÇÃO | B2: 2019/09/27 | C2: -0.0053204153 | K2: ESTIMAÇÃO | L2: 2019/09/27 | M2: 0.00058993571 | V2: ESTIMAÇÃO | W2: 2019/09/27 | X2: 0.01623388 | AD2: ESTIMAÇÃO | AE2: 2019/09/27 | AF2: 0.046774649 | AG2: =RESULTADOS_R!$T$18 -> 0.004364 | AH2: =AF2-AG2 -> 0.042410649 | AJ2: ESTIMAÇÃO | AK2: 2019/09/27 | AL2: -0.005901294 | AT2: ESTIMAÇÃO | AU2: 2019/09/27 | AV2: -0.014469346 | BB2: ESTIMAÇÃO | BC2: 2019/09/27 | BD2: -0.0002320408
A3: ESTIMAÇÃO | B3: 2019/09/30 | C3: 0.0050181127 | D3: -0.0053204153 | K3: ESTIMAÇÃO | L3: 2019/09/30 | M3: 0.00047169812 | N3: 0.00058993571 | V3: ESTIMAÇÃO | W3: 2019/09/30 | X3: 0.005079536 | Y3: 0.01623388 | AD3: ESTIMAÇÃO | AE3: 2019/09/30 | AF3: 0.029113467 | AG3: =RESULTADOS_R!$T$18 -> 0.004364 | AH3: =AF3-AG3 -> 0.024749467 | AJ3: ESTIMAÇÃO | AK3: 2019/09/30 | AL3: -0.016631182 | AM3: -0.005901294 | AT3: ESTIMAÇÃO | AU3: 2019/09/30 | AV3: -0.031809928 | AW3: -0.014469346 | BB3: ESTIMAÇÃO | BC3: 2019/09/30 | BD3: 0.002700444 | BE3: -0.0002320408 | BF3: =RESULTADOS_R!$T$27+(RESULTADOS_R!$T$28*BD2) -> 2.1371675e-05 | BG3: =BD3-BF3 -> 0.0026790723
A4: ESTIMAÇÃO | B4: 2019/10/01 | C4: -0.012337698 | D4: 0.0050181127 | E4: -0.0053204153 | K4: ESTIMAÇÃO | L4: 2019/10/01 | M4: -0.00047169812 | N4: 0.00047169812 | O4: 0.00058993571 | V4: ESTIMAÇÃO | W4: 2019/10/01 | X4: 0.0059396114 | Y4: 0.005079536 | Z4: 0.01623388 | AA4: =RESULTADOS_R!$T$15+(RESULTADOS_R!$T$16*'EV1-ER-AR'!X3)+(RESULTADOS_R!$T$17*'EV1-ER-AR'!X2) -> -0.00080868887 | AB4: =X4-AA4 -> 0.0067483002 | AD4: ESTIMAÇÃO | AE4: 2019/10/01 | AF4: -0.014175447 | AG4: =RESULTADOS_R!$T$18 -> 0.004364 | AH4: =AF4-AG4 -> -0.018539447 | AJ4: ESTIMAÇÃO | AK4: 2019/10/01 | AL4: 0.0045608181 | AM4: -0.016631182 | AN4: -0.005901294 | AT4: ESTIMAÇÃO | AU4: 2019/10/01 | AV4: 0.014023017 | AW4: -0.031809928 | AX4: -0.014469346 | AY4: =RESULTADOS_R!$T$24+(RESULTADOS_R!$T$25*AV3)+(RESULTADOS_R!$T$26*AV2) -> 0.0038737867 | AZ4: =AV4-AY4 -> 0.01014923 | BB4: ESTIMAÇÃO | BC4: 2019/10/01 | BD4: -0.0025087542 | BE4: 0.002700444 | BF4: =RESULTADOS_R!$T$27+(RESULTADOS_R!$T$28*BD3) -> 0.00058093957 | BG4: =BD4-BF4 -> -0.0030896938
A5: ESTIMAÇÃO | B5: 2019/10/02 | C5: -0.018051899 | D5: -0.012337698 | E5: 0.0050181127 | F5: -0.0053204153 | K5: ESTIMAÇÃO | L5: 2019/10/02 | M5: 0.0010610081 | N5: -0.00047169812 | O5: 0.00047169812 | P5: 0.00058993571 | V5: ESTIMAÇÃO | W5: 2019/10/02 | X5: 0.0059469603 | Y5: 0.0059396114 | Z5: 0.005079536 | AA5: =RESULTADOS_R!$T$15+(RESULTADOS_R!$T$16*'EV1-ER-AR'!X4)+(RESULTADOS_R!$T$17*'EV1-ER-AR'!X3) -> 0.0018982891 | AB5: =X5-AA5 -> 0.0040486712 | AD5: ESTIMAÇÃO | AE5: 2019/10/02 | AF5: 0.018825178 | AG5: =RESULTADOS_R!$T$18 -> 0.004364 | AH5: =AF5-AG5 -> 0.014461178 | AJ5: ESTIMAÇÃO | AK5: 2019/10/02 | AL5: 0.013785727 | AM5: 0.0045608181 | AN5: -0.016631182 | AO5: -0.005901294 | AT5: ESTIMAÇÃO | AU5: 2019/10/02 | AV5: 0.01839661 | AW5: 0.014023017 | AX5: -0.031809928 | AY5: =RESULTADOS_R!$T$24+(RESULTADOS_R!$T$25*AV4)+(RESULTADOS_R!$T$26*AV3) -> 0.0033210295 | AZ5: =AV5-AY5 -> 0.01507558 | BB5: ESTIMAÇÃO | BC5: 2019/10/02 | BD5: -0.0011001934 | BE5: -0.0025087542 | BF5: =RESULTADOS_R!$T$27+(RESULTADOS_R!$T$28*BD4) -> -0.00041306391 | BG5: =BD5-BF5 -> -0.00068712949
A6: ESTIMAÇÃO | B6: 2019/10/03 | C6: 0.0079335382 | D6: -0.018051899 | E6: -0.012337698 | F6: 0.0050181127 | G6: -0.0053204153 | H6: =RESULTADOS_R!$T$4+(RESULTADOS_R!$T$5*C5)+(RESULTADOS_R!$T$6*C4)+(RESULTADOS_R!$T$7*C3)+(RESULTADOS_R!$T$8*C2) -> 0.0037198407 | I6: =C6-H6 -> 0.0042136976 | K6: ESTIMAÇÃO | L6: 2019/10/03 | M6: 0.0021186449 | N6: 0.0010610081 | O6: -0.00047169812 | P6: 0.00047169812 | Q6: 0.00058993571 | V6: ESTIMAÇÃO | W6: 2019/10/03 | X6: -0.015979371 | Y6: 0.0059469603 | Z6: 0.0059396114 | AA6: =RESULTADOS_R!$T$15+(RESULTADOS_R!$T$16*'EV1-ER-AR'!X5)+(RESULTADOS_R!$T$17*'EV1-ER-AR'!X4) -> 0.0017069229 | AB6: =X6-AA6 -> -0.017686293 | AD6: ESTIMAÇÃO | AE6: 2019/10/03 | AF6: -0.030971918 | AG6: =RESULTADOS_R!$T$18 -> 0.004364 | AH6: =AF6-AG6 -> -0.035335918 | AJ6: ESTIMAÇÃO | AK6: 2019/10/03 | AL6: 0.0036545101 | AM6: 0.013785727 | AN6: 0.0045608181 | AO6: -0.016631182 | AP6: -0.005901294 | AQ6: =RESULTADOS_R!$T$19+(RESULTADOS_R!$T$20*AL5)+(RESULTADOS_R!$T$21*AL4)+(RESULTADOS_R!$T$22*AL3)+(RESULTADOS_R!$T$23*AL2) -> 0.0046161981 | AR6: =AL6-AQ6 -> -0.00096168797 | AT6: ESTIMAÇÃO | AU6: 2019/10/03 | AV6: 0 | AW6: 0.01839661 | AX6: 0.014023017 | AY6: =RESULTADOS_R!$T$24+(RESULTADOS_R!$T$25*AV5)+(RESULTADOS_R!$T$26*AV4) -> -0.0015000294 | AZ6: =AV6-AY6 -> 0.0015000294 | BB6: ESTIMAÇÃO | BC6: 2019/10/03 | BD6: -0.0015665826 | BE6: -0.0011001934 | BF6: =RESULTADOS_R!$T$27+(RESULTADOS_R!$T$28*BD5) -> -0.00014428658 | BG6: =BD6-BF6 -> -0.001422296
A7: ESTIMAÇÃO | B7: 2019/10/04 | C7: 0.014123661 | D7: 0.0079335382 | E7: -0.018051899 | F7: -0.012337698 | G7: 0.0050181127 | H7: =RESULTADOS_R!$T$4+(RESULTADOS_R!$T$5*C6)+(RESULTADOS_R!$T$6*C5)+(RESULTADOS_R!$T$7*C4)+(RESULTADOS_R!$T$8*C3) -> 0.0084224245 | I7: =C7-H7 -> 0.0057012367 | K7: ESTIMAÇÃO | L7: 2019/10/04 | M7: -0.00011758481 | N7: 0.0021186449 | O7: 0.0010610081 | P7: -0.00047169812 | Q7: 0.00047169812 | R7: 0.00058993571 | S7: =RESULTADOS_R!$T$9+(RESULTADOS_R!$T$10*M6)+(RESULTADOS_R!$T$11*M5)+(RESULTADOS_R!$T$12*M4)+(RESULTADOS_R!$T$13*M3)+(RESULTADOS_R!$T$14*M2) -> -0.00020236888 | T7: =M7-S7 -> 8.4784072e-05 | V7: ESTIMAÇÃO | W7: 2019/10/04 | X7: -0.0065654266 | Y7: -0.015979371 | Z7: 0.0059469603 | AA7: =RESULTADOS_R!$T$15+(RESULTADOS_R!$T$16*'EV1-ER-AR'!X6)+(RESULTADOS_R!$T$17*'EV1-ER-AR'!X5) -> -0.0034618204 | AB7: =X7-AA7 -> -0.0031036062 | AD7: ESTIMAÇÃO | AE7: 2019/10/04 | AF7: 0.010140602 | AG7: =RESULTADOS_R!$T$18 -> 0.004364 | AH7: =AF7-AG7 -> 0.0057766022 | AJ7: ESTIMAÇÃO | AK7: 2019/10/04 | AL7: -0.00026581606 | AM7: 0.0036545101 | AN7: 0.013785727 | AO7: 0.0045608181 | AP7: -0.016631182 | AQ7: =RESULTADOS_R!$T$19+(RESULTADOS_R!$T$20*AL6)+(RESULTADOS_R!$T$21*AL5)+(RESULTADOS_R!$T$22*AL4)+(RESULTADOS_R!$T$23*AL3) -> -0.00075785393 | AR7: =AL7-AQ7 -> 0.00049203787 | AT7: ESTIMAÇÃO | AU7: 2019/10/04 | AV7: -0.00028485971 | AW7: 0 | AX7: 0.01839661 | AY7: =RESULTADOS_R!$T$24+(RESULTADOS_R!$T$25*AV6)+(RESULTADOS_R!$T$26*AV5) -> -0.001018433 | AZ7: =AV7-AY7 -> 0.0007335733 | BB7: ESTIMAÇÃO | BC7: 2019/10/04 | BD7: -0.00056659518 | BE7: -0.0015665826 | BF7: =RESULTADOS_R!$T$27+(RESULTADOS_R!$T$28*BD6) -> -0.00023328156 | BG7: =BD7-BF7 -> -0.00033331362
A8: ESTIMAÇÃO | B8: 2019/10/07 | C8: -0.004481572 | D8: 0.014123661 | E8: 0.0079335382 | F8: -0.018051899 | G8: -0.012337698 | H8: =RESULTADOS_R!$T$4+(RESULTADOS_R!$T$5*C7)+(RESULTADOS_R!$T$6*C6)+(RESULTADOS_R!$T$7*C5)+(RESULTADOS_R!$T$8*C4) -> 0.0016335737 | I8: =C8-H8 -> -0.0061151457 | K8: ESTIMAÇÃO | L8: 2019/10/07 | M8: -0.0010588859 | N8: -0.00011758481 | O8: 0.0021186449 | P8: 0.0010610081 | Q8: -0.00047169812 | R8: 0.00047169812 | S8: =RESULTADOS_R!$T$9+(RESULTADOS_R!$T$10*M7)+(RESULTADOS_R!$T$11*M6)+(RESULTADOS_R!$T$12*M5)+(RESULTADOS_R!$T$13*M4)+(RESULTADOS_R!$T$14*M3) -> -0.00017419235 | T8: =M8-S8 -> -0.00088469357 | V8: ESTIMAÇÃO | W8: 2019/10/07 | X8: 0.0048243162 | Y8: -0.0065654266 | Z8: -0.015979371 | AA8: =RESULTADOS_R!$T$15+(RESULTADOS_R!$T$16*'EV1-ER-AR'!X7)+(RESULTADOS_R!$T$17*'EV1-ER-AR'!X6) -> 0.0036793877 | AB8: =X8-AA8 -> 0.0011449285 | AD8: ESTIMAÇÃO | AE8: 2019/10/07 | AF8: 0.023460946 | AG8: =RESULTADOS_R!$T$18 -> 0.004364 | AH8: =AF8-AG8 -> 0.019096946 | AJ8: ESTIMAÇÃO | AK8: 2019/10/07 | AL8: -0.0073377689 | AM8: -0.00026581606 | AN8: 0.0036545101 | AO8: 0.013785727 | AP8: 0.0045608181 | AQ8: =RESULTADOS_R!$T$19+(RESULTADOS_R!$T$20*AL7)+(RESULTADOS_R!$T$21*AL6)+(RESULTADOS_R!$T$22*AL5)+(RESULTADOS_R!$T$23*AL4) -> -0.0012826397 | AR8: =AL8-AQ8 -> -0.0060551292 | AT8: ESTIMAÇÃO | AU8: 2019/10/07 | AV8: -0.0065742698 | AW8: -0.00028485971 | AX8: 0 | AY8: =RESULTADOS_R!$T$24+(RESULTADOS_R!$T$25*AV7)+(RESULTADOS_R!$T$26*AV6) -> 0.00084305731 | AZ8: =AV8-AY8 -> -0.0074173271 | BB8: ESTIMAÇÃO | BC8: 2019/10/07 | BD8: 0.0016078881 | BE8: -0.00056659518 | BF8: =RESULTADOS_R!$T$27+(RESULTADOS_R!$T$28*BD7) -> -4.2466982e-05 | BG8: =BD8-BF8 -> 0.0016503551
A9: ESTIMAÇÃO | B9: 2019/10/08 | C9: -0.015672743 | D9: -0.004481572 | E9: 0.014123661 | F9: 0.0079335382 | G9: -0.018051899 | H9: =RESULTADOS_R!$T$4+(RESULTADOS_R!$T$5*C8)+(RESULTADOS_R!$T$6*C7)+(RESULTADOS_R!$T$7*C6)+(RESULTADOS_R!$T$8*C5) -> -0.0053046936 | I9: =C9-H9 -> -0.01036805 | K9: ESTIMAÇÃO | L9: 2019/10/08 | M9: 0.00058840837 | N9: -0.0010588859 | O9: -0.00011758481 | P9: 0.0021186449 | Q9: 0.0010610081 | R9: -0.00047169812 | S9: =RESULTADOS_R!$T$9+(RESULTADOS_R!$T$10*M8)+(RESULTADOS_R!$T$11*M7)+(RESULTADOS_R!$T$12*M6)+(RESULTADOS_R!$T$13*M5)+(RESULTADOS_R!$T$14*M4) -> -0.00015796273 | T9: =M9-S9 -> 0.0007463711 | V9: ESTIMAÇÃO | W9: 2019/10/08 | X9: -0.0020443573 | Y9: 0.0048243162 | Z9: -0.0065654266 | AA9: =RESULTADOS_R!$T$15+(RESULTADOS_R!$T$16*'EV1-ER-AR'!X8)+(RESULTADOS_R!$T$17*'EV1-ER-AR'!X7) -> 0.0042499075 | AB9: =X9-AA9 -> -0.0062942648 | AD9: ESTIMAÇÃO | AE9: 2019/10/08 | AF9: 0.0045991949 | AG9: =RESULTADOS_R!$T$18 -> 0.004364 | AH9: =AF9-AG9 -> 0.00023519493 | AJ9: ESTIMAÇÃO | AK9: 2019/10/08 | AL9: 0.007942398 | AM9: -0.0073377689 | AN9: -0.00026581606 | AO9: 0.0036545101 | AP9: 0.013785727 | AQ9: =RESULTADOS_R!$T$19+(RESULTADOS_R!$T$20*AL8)+(RESULTADOS_R!$T$21*AL7)+(RESULTADOS_R!$T$22*AL6)+(RESULTADOS_R!$T$23*AL5) -> 0.00079754386 | AR9: =AL9-AQ9 -> 0.0071448541 | AT9: ESTIMAÇÃO | AU9: 2019/10/08 | AV9: 0.015649772 | AW9: -0.0065742698 | AX9: -0.00028485971 | AY9: =RESULTADOS_R!$T$24+(RESULTADOS_R!$T$25*AV8)+(RESULTADOS_R!$T$26*AV7) -> 0.0011864474 | AZ9: =AV9-AY9 -> 0.014463324 | BB9: ESTIMAÇÃO | BC9: 2019/10/08 | BD9: 0.0016759216 | BE9: 0.0016078881 | BF9: =RESULTADOS_R!$T$27+(RESULTADOS_R!$T$28*BD8) -> 0.00037246135 | BG9: =BD9-BF9 -> 0.0013034603
A10: ESTIMAÇÃO | B10: 2019/10/09 | C10: 0.0090495241 | D10: -0.015672743 | E10: -0.004481572 | F10: 0.014123661 | G10: 0.0079335382 | H10: =RESULTADOS_R!$T$4+(RESULTADOS_R!$T$5*C9)+(RESULTADOS_R!$T$6*C8)+(RESULTADOS_R!$T$7*C7)+(RESULTADOS_R!$T$8*C6) -> 0.0023414337 | I10: =C10-H10 -> 0.0067080904 | K10: ESTIMAÇÃO | L10: 2019/10/09 | M10: -0.00058840837 | N10: 0.00058840837 | O10: -0.0010588859 | P10: -0.00011758481 | Q10: 0.0021186449 | R10: 0.0010610081 | S10: =RESULTADOS_R!$T$9+(RESULTADOS_R!$T$10*M9)+(RESULTADOS_R!$T$11*M8)+(RESULTADOS_R!$T$12*M7)+(RESULTADOS_R!$T$13*M6)+(RESULTADOS_R!$T$14*M5) -> -0.00011922603 | T10: =M10-S10 -> -0.00046918235 | V10: ESTIMAÇÃO | W10: 2019/10/09 | X10: 0.043628562 | Y10: -0.0020443573 | Z10: 0.0048243162 | AA10: =RESULTADOS_R!$T$15+(RESULTADOS_R!$T$16*'EV1-ER-AR'!X9)+(RESULTADOS_R!$T$17*'EV1-ER-AR'!X8) -> 7.4111197e-05 | AB10: =X10-AA10 -> 0.043554451 | AD10: ESTIMAÇÃO | AE10: 2019/10/09 | AF10: 0.060083344 | AG10: =RESULTADOS_R!$T$18 -> 0.004364 | AH10: =AF10-AG10 -> 0.055719344 | AJ10: ESTIMAÇÃO | AK10: 2019/10/09 | AL10: 0.00012619512 | AM10: 0.007942398 | AN10: -0.0073377689 | AO10: -0.00026581606 | AP10: 0.0036545101 | AQ10: =RESULTADOS_R!$T$19+(RESULTADOS_R!$T$20*AL9)+(RESULTADOS_R!$T$21*AL8)+(RESULTADOS_R!$T$22*AL7)+(RESULTADOS_R!$T$23*AL6) -> 0.0014186389 | AR10: =AL10-AQ10 -> -0.0012924438 | AT10: ESTIMAÇÃO | AU10: 2019/10/09 | AV10: -0.00056481221 | AW10: 0.015649772 | AX10: -0.0065742698 | AY10: =RESULTADOS_R!$T$24+(RESULTADOS_R!$T$25*AV9)+(RESULTADOS_R!$T$26*AV8) -> 0.00070565718 | AZ10: =AV10-AY10 -> -0.0012704694 | BB10: ESTIMAÇÃO | BC10: 2019/10/09 | BD10: -0.00015132332 | BE10: 0.0016759216 | BF10: =RESULTADOS_R!$T$27+(RESULTADOS_R!$T$28*BD9) -> 0.00038544331 | BG10: =BD10-BF10 -> -0.00053676663
A11: ESTIMAÇÃO | B11: 2019/10/10 | C11: 0.0063849982 | D11: 0.0090495241 | E11: -0.015672743 | F11: -0.004481572 | G11: 0.014123661 | H11: =RESULTADOS_R!$T$4+(RESULTADOS_R!$T$5*C10)+(RESULTADOS_R!$T$6*C9)+(RESULTADOS_R!$T$7*C8)+(RESULTADOS_R!$T$8*C7) -> 0.0076086964 | I11: =C11-H11 -> -0.0012236982 | K11: ESTIMAÇÃO | L11: 2019/10/10 | M11: -0.0011778564 | N11: -0.00058840837 | O11: 0.00058840837 | P11: -0.0010588859 | Q11: -0.00011758481 | R11: 0.0021186449 | S11: =RESULTADOS_R!$T$9+(RESULTADOS_R!$T$10*M10)+(RESULTADOS_R!$T$11*M9)+(RESULTADOS_R!$T$12*M8)+(RESULTADOS_R!$T$13*M7)+(RESULTADOS_R!$T$14*M6) -> 5.7798163e-05 | T11: =M11-S11 -> -0.0012356546 | V11: ESTIMAÇÃO | W11: 2019/10/10 | X11: -0.0010786029 | Y11: 0.043628562 | Z11: -0.0020443573 | AA11: =RESULTADOS_R!$T$15+(RESULTADOS_R!$T$16*'EV1-ER-AR'!X10)+(RESULTADOS_R!$T$17*'EV1-ER-AR'!X9) -> 0.012379361 | AB11: =X11-AA11 -> -0.013457964 | AD11: ESTIMAÇÃO | AE11: 2019/10/10 | AF11: -0.0084872471 | AG11: =RESULTADOS_R!$T$18 -> 0.004364 | AH11: =AF11-AG11 -> -0.012851247 | AJ11: ESTIMAÇÃO | AK11: 2019/10/10 | AL11: -0.0076000366 | AM11: 0.00012619512 | AN11: 0.007942398 | AO11: -0.0073377689 | AP11: -0.00026581606 | AQ11: =RESULTADOS_R!$T$19+(RESULTADOS_R!$T$20*AL10)+(RESULTADOS_R!$T$21*AL9)+(RESULTADOS_R!$T$22*AL8)+(RESULTADOS_R!$T$23*AL7) -> 0.0025057893 | AR11: =AL11-AQ11 -> -0.010105826 | AT11: ESTIMAÇÃO | AU11: 2019/10/10 | AV11: -0.012507269 | AW11: -0.00056481221 | AX11: 0.015649772 | AY11: =RESULTADOS_R!$T$24+(RESULTADOS_R!$T$25*AV10)+(RESULTADOS_R!$T$26*AV9) -> -0.00071434959 | AZ11: =AV11-AY11 -> -0.01179292 | BB11: ESTIMAÇÃO | BC11: 2019/10/10 | BD11: -0.0042159815 | BE11: -0.00015132332 | BF11: =RESULTADOS_R!$T$27+(RESULTADOS_R!$T$28*BD10) -> 3.677394e-05 | BG11: =BD11-BF11 -> -0.0042527554
A12: ESTIMAÇÃO | B12: 2019/10/11 | C12: 0.010899844 | D12: 0.0063849982 | E12: 0.0090495241 | F12: -0.015672743 | G12: -0.004481572 | H12: =RESULTADOS_R!$T$4+(RESULTADOS_R!$T$5*C11)+(RESULTADOS_R!$T$6*C10)+(RESULTADOS_R!$T$7*C9)+(RESULTADOS_R!$T$8*C8) -> 0.0031674298 | I12: =C12-H12 -> 0.0077324141 | K12: ESTIMAÇÃO | L12: 2019/10/11 | M12: -0.00094328506 | N12: -0.0011778564 | O12: -0.00058840837 | P12: 0.00058840837 | Q12: -0.0010588859 | R12: -0.00011758481 | S12: =RESULTADOS_R!$T$9+(RESULTADOS_R!$T$10*M11)+(RESULTADOS_R!$T$11*M10)+(RESULTADOS_R!$T$12*M9)+(RESULTADOS_R!$T$13*M8)+(RESULTADOS_R!$T$14*M7) -> -6.7615558e-06 | T12: =M12-S12 -> -0.0009365235 | V12: ESTIMAÇÃO | W12: 2019/10/11 | X12: -0.031314732 | Y12: -0.0010786029 | Z12: 0.043628562 | AA12: =RESULTADOS_R!$T$15+(RESULTADOS_R!$T$16*'EV1-ER-AR'!X11)+(RESULTADOS_R!$T$17*'EV1-ER-AR'!X10) -> -0.0084103596 | AB12: =X12-AA12 -> -0.022904372 | AD12: ESTIMAÇÃO | AE12: 2019/10/11 | AF12: -0.048589286 | AG12: =RESULTADOS_R!$T$18 -> 0.004364 | AH12: =AF12-AG12 -> -0.052953286 | AJ12: ESTIMAÇÃO | AK12: 2019/10/11 | AL12: -0.002982426 | AM12: -0.0076000366 | AN12: 0.00012619512 | AO12: 0.007942398 | AP12: -0.0073377689 | AQ12: =RESULTADOS_R!$T$19+(RESULTADOS_R!$T$20*AL11)+(RESULTADOS_R!$T$21*AL10)+(RESULTADOS_R!$T$22*AL9)+(RESULTADOS_R!$T$23*AL8) -> -0.0019986103 | AR12: =AL12-AQ12 -> -0.00098381569 | AT12: ESTIMAÇÃO | AU12: 2019/10/11 | AV12: 0.0034266167 | AW12: -0.012507269 | AX12: -0.00056481221 | AY12: =RESULTADOS_R!$T$24+(RESULTADOS_R!$T$25*AV11)+(RESULTADOS_R!$T$26*AV10) -> 0.0015115063 | AZ12: =AV12-AY12 -> 0.0019151104 | BB12: ESTIMAÇÃO | BC12: 2019/10/11 | BD12: -0.0040608781 | BE12: -0.0042159815 | BF12: =RESULTADOS_R!$T$27+(RESULTADOS_R!$T$28*BD11) -> -0.00073883185 | BG12: =BD12-BF12 -> -0.0033220462
A13: ESTIMAÇÃO | B13: 2019/10/14 | C13: -0.0013812855 | D13: 0.010899844 | E13: 0.0063849982 | F13: 0.0090495241 | G13: -0.015672743 | H13: =RESULTADOS_R!$T$4+(RESULTADOS_R!$T$5*C12)+(RESULTADOS_R!$T$6*C11)+(RESULTADOS_R!$T$7*C10)+(RESULTADOS_R!$T$8*C9) -> -0.005507295 | I13: =C13-H13 -> 0.0041260095 | K13: ESTIMAÇÃO | L13: 2019/10/14 | M13: 0.0001179593 | N13: -0.00094328506 | O13: -0.0011778564 | P13: -0.00058840837 | Q13: 0.00058840837 | R13: -0.0010588859 | S13: =RESULTADOS_R!$T$9+(RESULTADOS_R!$T$10*M12)+(RESULTADOS_R!$T$11*M11)+(RESULTADOS_R!$T$12*M10)+(RESULTADOS_R!$T$13*M9)+(RESULTADOS_R!$T$14*M8) -> 0.00030199079 | T13: =M13-S13 -> -0.00018403148 | V13: ESTIMAÇÃO | W13: 2019/10/14 | X13: 0.006340262 | Y13: -0.031314732 | Z13: -0.0010786029 | AA13: =RESULTADOS_R!$T$15+(RESULTADOS_R!$T$16*'EV1-ER-AR'!X12)+(RESULTADOS_R!$T$17*'EV1-ER-AR'!X11) -> -0.0054983754 | AB13: =X13-AA13 -> 0.011838637 | AD13: ESTIMAÇÃO | AE13: 2019/10/14 | AF13: 0.023767565 | AG13: =RESULTADOS_R!$T$18 -> 0.004364 | AH13: =AF13-AG13 -> 0.019403565 | AJ13: ESTIMAÇÃO | AK13: 2019/10/14 | AL13: 0.0020450933 | AM13: -0.002982426 | AN13: -0.0076000366 | AO13: 0.00012619512 | AP13: 0.007942398 | AQ13: =RESULTADOS_R!$T$19+(RESULTADOS_R!$T$20*AL12)+(RESULTADOS_R!$T$21*AL11)+(RESULTADOS_R!$T$22*AL10)+(RESULTADOS_R!$T$23*AL9) -> 0.00091327407 | AR13: =AL13-AQ13 -> 0.0011318193 | AT13: ESTIMAÇÃO | AU13: 2019/10/14 | AV13: 0.0062517964 | AW13: 0.0034266167 | AX13: -0.012507269 | AY13: =RESULTADOS_R!$T$24+(RESULTADOS_R!$T$25*AV12)+(RESULTADOS_R!$T$26*AV11) -> 0.0019131717 | AZ13: =AV13-AY13 -> 0.0043386247 | BB13: ESTIMAÇÃO | BC13: 2019/10/14 | BD13: 0.001555234 | BE13: -0.0040608781 | BF13: =RESULTADOS_R!$T$27+(RESULTADOS_R!$T$28*BD12) -> -0.00070923549 | BG13: =BD13-BF13 -> 0.0022644695
A14: ESTIMAÇÃO | B14: 2019/10/15 | C14: 0.0098962548 | D14: -0.0013812855 | E14: 0.010899844 | F14: 0.0063849982 | G14: 0.0090495241 | H14: =RESULTADOS_R!$T$4+(RESULTADOS_R!$T$5*C13)+(RESULTADOS_R!$T$6*C12)+(RESULTADOS_R!$T$7*C11)+(RESULTADOS_R!$T$8*C10) -> 0.00052330878 | I14: =C14-H14 -> 0.009372946 | K14: ESTIMAÇÃO | L14: 2019/10/15 | M14: -0.00023593252 | N14: 0.0001179593 | O14: -0.00094328506 | P14: -0.0011778564 | Q14: -0.00058840837 | R14: 0.00058840837 | S14: =RESULTADOS_R!$T$9+(RESULTADOS_R!$T$10*M13)+(RESULTADOS_R!$T$11*M12)+(RESULTADOS_R!$T$12*M11)+(RESULTADOS_R!$T$13*M10)+(RESULTADOS_R!$T$14*M9) -> 7.2008167e-05 | T14: =M14-S14 -> -0.00030794069 | V14: ESTIMAÇÃO | W14: 2019/10/15 | X14: -0.020424903 | Y14: 0.006340262 | Z14: -0.031314732 | AA14: =RESULTADOS_R!$T$15+(RESULTADOS_R!$T$16*'EV1-ER-AR'!X13)+(RESULTADOS_R!$T$17*'EV1-ER-AR'!X12) -> 0.010163691 | AB14: =X14-AA14 -> -0.030588595 | AD14: ESTIMAÇÃO | AE14: 2019/10/15 | AF14: -0.030161596 | AG14: =RESULTADOS_R!$T$18 -> 0.004364 | AH14: =AF14-AG14 -> -0.034525596 | AJ14: ESTIMAÇÃO | AK14: 2019/10/15 | AL14: -0.0078882211 | AM14: 0.0020450933 | AN14: -0.002982426 | AO14: -0.0076000366 | AP14: 0.00012619512 | AQ14: =RESULTADOS_R!$T$19+(RESULTADOS_R!$T$20*AL13)+(RESULTADOS_R!$T$21*AL12)+(RESULTADOS_R!$T$22*AL11)+(RESULTADOS_R!$T$23*AL10) -> 0.0022380232 | AR14: =AL14-AQ14 -> -0.010126244 | AT14: ESTIMAÇÃO | AU14: 2019/10/15 | AV14: -0.015991203 | AW14: 0.0062517964 | AX14: 0.0034266167 | AY14: =RESULTADOS_R!$T$24+(RESULTADOS_R!$T$25*AV13)+(RESULTADOS_R!$T$26*AV12) -> 0.00017182365 | AZ14: =AV14-AY14 -> -0.016163027 | BB14: ESTIMAÇÃO | BC14: 2019/10/15 | BD14: -0.0016874896 | BE14: 0.001555234 | BF14: =RESULTADOS_R!$T$27+(RESULTADOS_R!$T$28*BD13) -> 0.00036241405 | BG14: =BD14-BF14 -> -0.0020499037
A15: ESTIMAÇÃO | B15: 2019/10/16 | C15: -0.0020048792 | D15: 0.0098962548 | E15: -0.0013812855 | F15: 0.010899844 | G15: 0.0063849982 | H15: =RESULTADOS_R!$T$4+(RESULTADOS_R!$T$5*C14)+(RESULTADOS_R!$T$6*C13)+(RESULTADOS_R!$T$7*C12)+(RESULTADOS_R!$T$8*C11) -> -0.00035489756 | I15: =C15-H15 -> -0.0016499817 | K15: ESTIMAÇÃO | L15: 2019/10/16 | M15: 0.0004718094 | N15: -0.00023593252 | O15: 0.0001179593 | P15: -0.00094328506 | Q15: -0.0011778564 | R15: -0.00058840837 | S15: =RESULTADOS_R!$T$9+(RESULTADOS_R!$T$10*M14)+(RESULTADOS_R!$T$11*M13)+(RESULTADOS_R!$T$12*M12)+(RESULTADOS_R!$T$13*M11)+(RESULTADOS_R!$T$14*M10) -> 0.00020183882 | T15: =M15-S15 -> 0.00026997058 | V15: ESTIMAÇÃO | W15: 2019/10/16 | X15: -0.019423912 | Y15: -0.020424903 | Z15: 0.006340262 | AA15: =RESULTADOS_R!$T$15+(RESULTADOS_R!$T$16*'EV1-ER-AR'!X14)+(RESULTADOS_R!$T$17*'EV1-ER-AR'!X13) -> -0.0045977427 | AB15: =X15-AA15 -> -0.01482617 | AD15: ESTIMAÇÃO | AE15: 2019/10/16 | AF15: -0.030177181 | AG15: =RESULTADOS_R!$T$18 -> 0.004364 | AH15: =AF15-AG15 -> -0.034541181 | AJ15: ESTIMAÇÃO | AK15: 2019/10/16 | AL15: 0.0057894296 | AM15: -0.0078882211 | AN15: 0.0020450933 | AO15: -0.002982426 | AP15: -0.0076000366 | AQ15: =RESULTADOS_R!$T$19+(RESULTADOS_R!$T$20*AL14)+(RESULTADOS_R!$T$21*AL13)+(RESULTADOS_R!$T$22*AL12)+(RESULTADOS_R!$T$23*AL11) -> 0.00011953267 | AR15: =AL15-AQ15 -> 0.005669897 | AT15: ESTIMAÇÃO | AU15: 2019/10/16 | AV15: 0.0011507481 | AW15: -0.015991203 | AX15: 0.0062517964 | AY15: =RESULTADOS_R!$T$24+(RESULTADOS_R!$T$25*AV14)+(RESULTADOS_R!$T$26*AV13) -> 0.0010014116 | AZ15: =AV15-AY15 -> 0.00014933648 | BB15: ESTIMAÇÃO | BC15: 2019/10/16 | BD15: -0.0029140578 | BE15: -0.0016874896 | BF15: =RESULTADOS_R!$T$27+(RESULTADOS_R!$T$28*BD14) -> -0.00025635267 | BG15: =BD15-BF15 -> -0.0026577051
A16: ESTIMAÇÃO | B16: 2019/10/17 | C16: 0.0027389956 | D16: -0.0020048792 | E16: 0.0098962548 | F16: -0.0013812855 | G16: 0.010899844 | H16: =RESULTADOS_R!$T$4+(RESULTADOS_R!$T$5*C15)+(RESULTADOS_R!$T$6*C14)+(RESULTADOS_R!$T$7*C13)+(RESULTADOS_R!$T$8*C12) -> 0.0031456957 | I16: =C16-H16 -> -0.00040670003 | K16: ESTIMAÇÃO | L16: 2019/10/17 | M16: 0 | N16: 0.0004718094 | O16: -0.00023593252 | P16: 0.0001179593 | Q16: -0.00094328506 | R16: -0.0011778564 | S16: =RESULTADOS_R!$T$9+(RESULTADOS_R!$T$10*M15)+(RESULTADOS_R!$T$11*M14)+(RESULTADOS_R!$T$12*M13)+(RESULTADOS_R!$T$13*M12)+(RESULTADOS_R!$T$14*M11) -> -1.6623496e-05 | T16: =M16-S16 -> 1.6623496e-05 | V16: ESTIMAÇÃO | W16: 2019/10/17 | X16: 0.0069820085 | Y16: -0.019423912 | Z16: -0.020424903 | AA16: =RESULTADOS_R!$T$15+(RESULTADOS_R!$T$16*'EV1-ER-AR'!X15)+(RESULTADOS_R!$T$17*'EV1-ER-AR'!X14) -> 0.0016472754 | AB16: =X16-AA16 -> 0.0053347331 | AD16: ESTIMAÇÃO | AE16: 2019/10/17 | AF16: 0.011382036 | AG16: =RESULTADOS_R!$T$18 -> 0.004364 | AH16: =AF16-AG16 -> 0.0070180365 | AJ16: ESTIMAÇÃO | AK16: 2019/10/17 | AL16: 0.0014220269 | AM16: 0.0057894296 | AN16: -0.0078882211 | AO16: 0.0020450933 | AP16: -0.002982426 | AQ16: =RESULTADOS_R!$T$19+(RESULTADOS_R!$T$20*AL15)+(RESULTADOS_R!$T$21*AL14)+(RESULTADOS_R!$T$22*AL13)+(RESULTADOS_R!$T$23*AL12) -> 0.00017063132 | AR16: =AL16-AQ16 -> 0.0012513956 | AT16: ESTIMAÇÃO | AU16: 2019/10/17 | AV16: 0.0074477571 | AW16: 0.0011507481 | AX16: -0.015991203 | AY16: =RESULTADOS_R!$T$24+(RESULTADOS_R!$T$25*AV15)+(RESULTADOS_R!$T$26*AV14) -> 0.002376907 | AZ16: =AV16-AY16 -> 0.0050708501 | BB16: ESTIMAÇÃO | BC16: 2019/10/17 | BD16: -0.0040386745 | BE16: -0.0029140578 | BF16: =RESULTADOS_R!$T$27+(RESULTADOS_R!$T$28*BD15) -> -0.00049040271 | BG16: =BD16-BF16 -> -0.0035482718
A17: ESTIMAÇÃO | B17: 2019/10/18 | C17: -0.0039103674 | D17: 0.0027389956 | E17: -0.0020048792 | F17: 0.0098962548 | G17: -0.0013812855 | H17: =RESULTADOS_R!$T$4+(RESULTADOS_R!$T$5*C16)+(RESULTADOS_R!$T$6*C15)+(RESULTADOS_R!$T$7*C14)+(RESULTADOS_R!$T$8*C13) -> -0.00072138941 | I17: =C17-H17 -> -0.003188978 | K17: ESTIMAÇÃO | L17: 2019/10/18 | M17: 0.00035371102 | N17: 0 | O17: 0.0004718094 | P17: -0.00023593252 | Q17: 0.0001179593 | R17: -0.00094328506 | S17: =RESULTADOS_R!$T$9+(RESULTADOS_R!$T$10*M16)+(RESULTADOS_R!$T$11*M15)+(RESULTADOS_R!$T$12*M14)+(RESULTADOS_R!$T$13*M13)+(RESULTADOS_R!$T$14*M12) -> 0.0001436391 | T17: =M17-S17 -> 0.00021007192 | V17: ESTIMAÇÃO | W17: 2019/10/18 | X17: -0.016259979 | Y17: 0.0069820085 | Z17: -0.019423912 | AA17: =RESULTADOS_R!$T$15+(RESULTADOS_R!$T$16*'EV1-ER-AR'!X16)+(RESULTADOS_R!$T$17*'EV1-ER-AR'!X15) -> 0.00764528 | AB17: =X17-AA17 -> -0.023905259 | AD17: ESTIMAÇÃO | AE17: 2019/10/18 | AF17: -0.025066072 | AG17: =RESULTADOS_R!$T$18 -> 0.004364 | AH17: =AF17-AG17 -> -0.029430072 | AJ17: ESTIMAÇÃO | AK17: 2019/10/18 | AL17: -0.0012005407 | AM17: 0.0014220269 | AN17: 0.0057894296 | AO17: -0.0078882211 | AP17: 0.0020450933 | AQ17: =RESULTADOS_R!$T$19+(RESULTADOS_R!$T$20*AL16)+(RESULTADOS_R!$T$21*AL15)+(RESULTADOS_R!$T$22*AL14)+(RESULTADOS_R!$T$23*AL13) -> 0.0028260559 | AR17: =AL17-AQ17 -> -0.0040265967 | AT17: ESTIMAÇÃO | AU17: 2019/10/18 | AV17: 0.0012036133 | AW17: 0.0074477571 | AX17: 0.0011507481 | AY17: =RESULTADOS_R!$T$24+(RESULTADOS_R!$T$25*AV16)+(RESULTADOS_R!$T$26*AV15) -> 0.00034048906 | AZ17: =AV17-AY17 -> 0.0008631242 | BB17: ESTIMAÇÃO | BC17: 2019/10/18 | BD17: -0.0033352349 | BE17: -0.0040386745 | BF17: =RESULTADOS_R!$T$27+(RESULTADOS_R!$T$28*BD16) -> -0.00070499867 | BG17: =BD17-BF17 -> -0.0026302363
A18: ESTIMAÇÃO | B18: 2019/10/21 | C18: 0.0068414557 | D18: -0.0039103674 | E18: 0.0027389956 | F18: -0.0020048792 | G18: 0.0098962548 | H18: =RESULTADOS_R!$T$4+(RESULTADOS_R!$T$5*C17)+(RESULTADOS_R!$T$6*C16)+(RESULTADOS_R!$T$7*C15)+(RESULTADOS_R!$T$8*C14) -> 0.0044978553 | I18: =C18-H18 -> 0.0023436004 | K18: ESTIMAÇÃO | L18: 2019/10/21 | M18: -0.0004716425 | N18: 0.00035371102 | O18: 0 | P18: 0.0004718094 | Q18: -0.00023593252 | R18: 0.0001179593 | S18: =RESULTADOS_R!$T$9+(RESULTADOS_R!$T$10*M17)+(RESULTADOS_R!$T$11*M16)+(RESULTADOS_R!$T$12*M15)+(RESULTADOS_R!$T$13*M14)+(RESULTADOS_R!$T$14*M13) -> -0.00015496613 | T18: =M18-S18 -> -0.00031667638 | V18: ESTIMAÇÃO | W18: 2019/10/21 | X18: 0.033364985 | Y18: -0.016259979 | Z18: 0.0069820085 | AA18: =RESULTADOS_R!$T$15+(RESULTADOS_R!$T$16*'EV1-ER-AR'!X17)+(RESULTADOS_R!$T$17*'EV1-ER-AR'!X16) -> -0.0037603295 | AB18: =X18-AA18 -> 0.037125314 | AD18: ESTIMAÇÃO | AE18: 2019/10/21 | AF18: 0.0074576469 | AG18: =RESULTADOS_R!$T$18 -> 0.004364 | AH18: =AF18-AG18 -> 0.0030936469 | AJ18: ESTIMAÇÃO | AK18: 2019/10/21 | AL18: -0.0037652166 | AM18: -0.0012005407 | AN18: 0.0014220269 | AO18: 0.0057894296 | AP18: -0.0078882211 | AQ18: =RESULTADOS_R!$T$19+(RESULTADOS_R!$T$20*AL17)+(RESULTADOS_R!$T$21*AL16)+(RESULTADOS_R!$T$22*AL15)+(RESULTADOS_R!$T$23*AL14) -> -0.0011010683 | AR18: =AL18-AQ18 -> -0.0026641482 | AT18: ESTIMAÇÃO | AU18: 2019/10/21 | AV18: 0.0013615869 | AW18: 0.0012036133 | AX18: 0.0074477571 | AY18: =RESULTADOS_R!$T$24+(RESULTADOS_R!$T$25*AV17)+(RESULTADOS_R!$T$26*AV16) -> 2.0717584e-05 | AZ18: =AV18-AY18 -> 0.0013408694 | BB18: ESTIMAÇÃO | BC18: 2019/10/21 | BD18: 0.00047274036 | BE18: -0.0033352349 | BF18: =RESULTADOS_R!$T$27+(RESULTADOS_R!$T$28*BD17) -> -0.00057077046 | BG18: =BD18-BF18 -> 0.0010435108
... A125: AJUSTE | B125: 2020/03/25 | C125: 0.011497415 | D125: 0.089670899 | E125: -0.029722814 | F125: -0.044340462 | G125: 0.0047009967 | H125: =RESULTADOS_R!$T$4+(RESULTADOS_R!$T$5*C124)+(RESULTADOS_R!$T$6*C123)+(RESULTADOS_R!$T$7*C122)+(RESULTADOS_R!$T$8*C121) -> 0.0099322198 | I125: =C125-H125 -> 0.001565195 | K125: AJUSTE | L125: 2020/03/25 | M125: 0.0011558023 | N125: -0.0013868025 | O125: 0.0011555351 | P125: 0.0026628091 | Q125: 0.0017404425 | R125: -0.0012766206 | S125: =RESULTADOS_R!$T$9+(RESULTADOS_R!$T$10*M124)+(RESULTADOS_R!$T$11*M123)+(RESULTADOS_R!$T$12*M122)+(RESULTADOS_R!$T$13*M121)+(RESULTADOS_R!$T$14*M120) -> -6.6953062e-05 | T125: =M125-S125 -> 0.0012227553 | V125: AJUSTE | W125: 2020/03/25 | X125: -0.0080115496 | Y125: 0.048444747 | Z125: 0.034491719 | AA125: =RESULTADOS_R!$T$15+(RESULTADOS_R!$T$16*'EV1-ER-AR'!X124)+(RESULTADOS_R!$T$17*'EV1-ER-AR'!X123) -> 0.0053115046 | AB125: =X125-AA125 -> -0.013323054 | AD125: AJUSTE | AE125: 2020/03/25 | AF125: -0.018661997 | AG125: =RESULTADOS_R!$T$18 -> 0.004364 | AH125: =AF125-AG125 -> -0.023025997 | AJ125: AJUSTE | AK125: 2020/03/25 | AL125: -0.0050930013 | AM125: 0.042968472 | AN125: 0.036418893 | AO125: 0.018348644 | AP125: -0.010347369 | AQ125: =RESULTADOS_R!$T$19+(RESULTADOS_R!$T$20*AL124)+(RESULTADOS_R!$T$21*AL123)+(RESULTADOS_R!$T$22*AL122)+(RESULTADOS_R!$T$23*AL121) -> 0.00119575 | AR125: =AL125-AQ125 -> -0.0062887513 | AT125: AJUSTE | AU125: 2020/03/25 | AV125: 0.011149941 | AW125: 0.074161879 | AX125: 0.051889301 | AY125: =RESULTADOS_R!$T$24+(RESULTADOS_R!$T$25*AV124)+(RESULTADOS_R!$T$26*AV123) -> -0.008093312 | AZ125: =AV125-AY125 -> 0.019243253 | BB125: AJUSTE | BC125: 2020/03/25 | BD125: -0.0097396493 | BE125: -0.0043808681 | BF125: =RESULTADOS_R!$T$27+(RESULTADOS_R!$T$28*BD124) -> -0.00077029503 | BG125: =BD125-BF125 -> -0.0089693543

Sheet EV2-ER-AR
A1: JANELA_EV2 | B1: DATA_EV2 | C1: R_SPX | D1: R_SPX_ESPERADO_EV2 | E1: AR_SPX_EV2 | G1: JANELA_EV2 | H1: DATA_EV2 | I1: R_SHY | J1: LAG1_SHY_EV2 | K1: LAG2_SHY_EV2 | L1: LAG3_SHY_EV2 | M1: LAG4_SHY_EV2 | N1: R_SHY_ESPERADO_EV2 | O1: AR_SHY_EV2 | Q1: JANELA_EV2 | R1: DATA_EV2 | S1: R_BTC | T1: R_BTC_ESPERADO_EV2 | U1: AR_BTC_EV2 | W1: JANELA_EV2 | X1: DATA_EV2 | Y1: R_ETH | Z1: R_ETH_ESPERADO_EV2 | AA1: AR_ETH_EV2 | AC1: JANELA_EV2 | AD1: DATA_EV2 | AE1: R_OURO | AF1: LAG1_OURO_EV2 | AG1: LAG2_OURO_EV2 | AH1: LAG3_OURO_EV2 | AI1: LAG4_OURO_EV2 | AJ1: R_OURO_ESPERADO_EV2 | AK1: AR_OURO_EV2 | AM1: JANELA_EV2 | AN1: DATA_EV2 | AO1: R_PRATA | AP1: LAG1_PRATA_EV2 | AQ1: LAG2_PRATA_EV2 | AR1: LAG3_PRATA_EV2 | AS1: LAG4_PRATA_EV2 | AT1: R_PRATA_ESPERADO_EV2 | AU1: AR_PRATA_EV2 | AW1: JANELA_EV2 | AX1: DATA_EV2 | AY1: R_DXY | AZ1: R_DXY_ESPERADO_EV2 | BA1: AR_DXY_EV2
A2: ESTIMAÇÃO | B2: 2021/09/13 | C2: 0.0022627232 | D2: =RESULTADOS_R!$T$31 -> 0.0002891 | E2: =C2-D2 -> 0.0019736232 | G2: ESTIMAÇÃO | H2: 2021/09/13 | I2: 0.00023196474 | Q2: ESTIMAÇÃO | R2: 2021/09/13 | S2: 0.0017621637 | T2: =RESULTADOS_R!$T$37 -> -0.001944 | U2: =S2-T2 -> 0.0037061637 | W2: ESTIMAÇÃO | X2: 2021/09/13 | Y2: 0.022782492 | Z2: =RESULTADOS_R!$T$38 -> -0.001799 | AA2: =Y2-Z2 -> 0.024581492 | AC2: ESTIMAÇÃO | AD2: 2021/09/13 | AE2: 0.0034349612 | AM2: ESTIMAÇÃO | AN2: 2021/09/13 | AO2: -8.4329475e-05 | AW2: ESTIMAÇÃO | AX2: 2021/09/13 | AY2: 0.0010040107 | AZ2: =RESULTADOS_R!$T$49 -> 0.0003559 | BA2: =AY2-AZ2 -> 0.00064811073
A3: ESTIMAÇÃO | B3: 2021/09/14 | C3: -0.0057452076 | D3: =RESULTADOS_R!$T$31 -> 0.0002891 | E3: =C3-D3 -> -0.0060343076 | G3: ESTIMAÇÃO | H3: 2021/09/14 | I3: 0.0001159622 | J3: 0.00023196474 | Q3: ESTIMAÇÃO | R3: 2021/09/14 | S3: 0.046272077 | T3: =RESULTADOS_R!$T$37 -> -0.001944 | U3: =S3-T3 -> 0.048216077 | W3: ESTIMAÇÃO | X3: 2021/09/14 | Y3: 0.042795715 | Z3: =RESULTADOS_R!$T$38 -> -0.001799 | AA3: =Y3-Z3 -> 0.044594715 | AC3: ESTIMAÇÃO | AD3: 2021/09/14 | AE3: 0.0059926356 | AF3: 0.0034349612 | AM3: ESTIMAÇÃO | AN3: 2021/09/14 | AO3: 0.0049633112 | AP3: -8.4329475e-05 | AW3: ESTIMAÇÃO | AX3: 2021/09/14 | AY3: -0.0005612581 | AZ3: =RESULTADOS_R!$T$49 -> 0.0003559 | BA3: =AY3-AZ3 -> -0.0009171581
A4: ESTIMAÇÃO | B4: 2021/09/15 | C4: 0.0084269532 | D4: =RESULTADOS_R!$T$31 -> 0.0002891 | E4: =C4-D4 -> 0.0081378532 | G4: ESTIMAÇÃO | H4: 2021/09/15 | I4: 0 | J4: 0.0001159622 | K4: 0.00023196474 | Q4: ESTIMAÇÃO | R4: 2021/09/15 | S4: 0.02275454 | T4: =RESULTADOS_R!$T$37 -> -0.001944 | U4: =S4-T4 -> 0.02469854 | W4: ESTIMAÇÃO | X4: 2021/09/15 | Y4: 0.052851888 | Z4: =RESULTADOS_R!$T$38 -> -0.001799 | AA4: =Y4-Z4 -> 0.054650888 | AC4: ESTIMAÇÃO | AD4: 2021/09/15 | AE4: -0.0064945764 | AF4: 0.0059926356 | AG4: 0.0034349612 | AM4: ESTIMAÇÃO | AN4: 2021/09/15 | AO4: -0.00058758107 | AP4: 0.0049633112 | AQ4: -8.4329475e-05 | AW4: ESTIMAÇÃO | AX4: 2021/09/15 | AY4: -0.0008100621 | AZ4: =RESULTADOS_R!$T$49 -> 0.0003559 | BA4: =AY4-AZ4 -> -0.0011659621
A5: ESTIMAÇÃO | B5: 2021/09/16 | C5: -0.0015411249 | D5: =RESULTADOS_R!$T$31 -> 0.0002891 | E5: =C5-D5 -> -0.0018302249 | G5: ESTIMAÇÃO | H5: 2021/09/16 | I5: -0.00034792694 | J5: 0 | K5: 0.0001159622 | L5: 0.00023196474 | Q5: ESTIMAÇÃO | R5: 2021/09/16 | S5: -0.0081907461 | T5: =RESULTADOS_R!$T$37 -> -0.001944 | U5: =S5-T5 -> -0.0062467461 | W5: ESTIMAÇÃO | X5: 2021/09/16 | Y5: -0.012241774 | Z5: =RESULTADOS_R!$T$38 -> -0.001799 | AA5: =Y5-Z5 -> -0.010442774 | AC5: ESTIMAÇÃO | AD5: 2021/09/16 | AE5: -0.022110444 | AF5: -0.0064945764 | AG5: 0.0059926356 | AH5: 0.0034349612 | AM5: ESTIMAÇÃO | AN5: 2021/09/16 | AO5: -0.038058476 | AP5: -0.00058758107 | AQ5: 0.0049633112 | AR5: -8.4329475e-05 | AW5: ESTIMAÇÃO | AX5: 2021/09/16 | AY5: 0.0041406141 | AZ5: =RESULTADOS_R!$T$49 -> 0.0003559 | BA5: =AY5-AZ5 -> 0.0037847141
A6: ESTIMAÇÃO | B6: 2021/09/17 | C6: -0.0091616036 | D6: =RESULTADOS_R!$T$31 -> 0.0002891 | E6: =C6-D6 -> -0.0094507036 | G6: ESTIMAÇÃO | H6: 2021/09/17 | I6: -0.00023201856 | J6: -0.00034792694 | K6: 0 | L6: 0.0001159622 | M6: 0.00023196474 | N6: =RESULTADOS_R!$T$32+(RESULTADOS_R!$T$33*I5)+(RESULTADOS_R!$T$34*I4)+(RESULTADOS_R!$T$35*I3)+(RESULTADOS_R!$T$36*I2) -> -0.00031965764 | O6: =I6-N6 -> 8.7639074e-05 | Q6: ESTIMAÇÃO | R6: 2021/09/17 | S6: -0.010854036 | T6: =RESULTADOS_R!$T$37 -> -0.001944 | U6: =S6-T6 -> -0.0089100364 | W6: ESTIMAÇÃO | X6: 2021/09/17 | Y6: -0.049582689 | Z6: =RESULTADOS_R!$T$38 -> -0.001799 | AA6: =Y6-Z6 -> -0.047783689 | AC6: ESTIMAÇÃO | AD6: 2021/09/17 | AE6: 0.00043905291 | AF6: -0.022110444 | AG6: -0.0064945764 | AH6: 0.0059926356 | AI6: 0.0034349612 | AJ6: =RESULTADOS_R!$T$39+(RESULTADOS_R!$T$40*AE5)+(RESULTADOS_R!$T$41*AE4)+(RESULTADOS_R!$T$42*AE3)+(RESULTADOS_R!$T$43*AE2) -> -9.4802752e-05 | AK6: =AE6-AJ6 -> 0.00053385566 | AM6: ESTIMAÇÃO | AN6: 2021/09/17 | AO6: -0.023720016 | AP6: -0.038058476 | AQ6: -0.00058758107 | AR6: 0.0049633112 | AS6: -8.4329475e-05 | AT6: =RESULTADOS_R!$T$44+(RESULTADOS_R!$T$45*AO5)+(RESULTADOS_R!$T$46*AO4)+(RESULTADOS_R!$T$47*AO3)+(RESULTADOS_R!$T$48*AO2) -> -0.010548489 | AU6: =AO6-AT6 -> -0.013171527 | AW6: ESTIMAÇÃO | AX6: 2021/09/17 | AY6: 0.0028260293 | AZ6: =RESULTADOS_R!$T$49 -> 0.0003559 | BA6: =AY6-AZ6 -> 0.0024701293
A7: ESTIMAÇÃO | B7: 2021/09/20 | C7: -0.017132161 | D7: =RESULTADOS_R!$T$31 -> 0.0002891 | E7: =C7-D7 -> -0.017421261 | G7: ESTIMAÇÃO | H7: 2021/09/20 | I7: 0.00023201856 | J7: -0.00023201856 | K7: -0.00034792694 | L7: 0 | M7: 0.0001159622 | N7: =RESULTADOS_R!$T$32+(RESULTADOS_R!$T$33*I6)+(RESULTADOS_R!$T$34*I5)+(RESULTADOS_R!$T$35*I4)+(RESULTADOS_R!$T$36*I3) -> -0.00023073904 | O7: =I7-N7 -> 0.0004627576 | Q7: ESTIMAÇÃO | R7: 2021/09/20 | S7: -0.098262379 | T7: =RESULTADOS_R!$T$37 -> -0.001944 | U7: =S7-T7 -> -0.096318379 | W7: ESTIMAÇÃO | X7: 2021/09/20 | Y7: -0.13849639 | Z7: =RESULTADOS_R!$T$38 -> -0.001799 | AA7: =Y7-Z7 -> -0.13669739 | AC7: ESTIMAÇÃO | AD7: 2021/09/20 | AE7: 0.0055258182 | AF7: 0.00043905291 | AG7: -0.022110444 | AH7: -0.0064945764 | AI7: 0.0059926356 | AJ7: =RESULTADOS_R!$T$39+(RESULTADOS_R!$T$40*AE6)+(RESULTADOS_R!$T$41*AE5)+(RESULTADOS_R!$T$42*AE4)+(RESULTADOS_R!$T$43*AE3) -> 0.0047642329 | AK7: =AE7-AJ7 -> 0.0007615853 | AM7: ESTIMAÇÃO | AN7: 2021/09/20 | AO7: -0.0066088171 | AP7: -0.023720016 | AQ7: -0.038058476 | AR7: -0.00058758107 | AS7: 0.0049633112 | AT7: =RESULTADOS_R!$T$44+(RESULTADOS_R!$T$45*AO6)+(RESULTADOS_R!$T$46*AO5)+(RESULTADOS_R!$T$47*AO4)+(RESULTADOS_R!$T$48*AO3) -> 0.0023915091 | AU7: =AO7-AT7 -> -0.0090003262 | AW7: ESTIMAÇÃO | AX7: 2021/09/20 | AY7: 0.00086876785 | AZ7: =RESULTADOS_R!$T$49 -> 0.0003559 | BA7: =AY7-AZ7 -> 0.00051286785
A8: ESTIMAÇÃO | B8: 2021/09/21 | C8: -0.00080349871 | D8: =RESULTADOS_R!$T$31 -> 0.0002891 | E8: =C8-D8 -> -0.0010925987 | G8: ESTIMAÇÃO | H8: 2021/09/21 | I8: 0.00023196474 | J8: 0.00023201856 | K8: -0.00023201856 | L8: -0.00034792694 | M8: 0 | N8: =RESULTADOS_R!$T$32+(RESULTADOS_R!$T$33*I7)+(RESULTADOS_R!$T$34*I6)+(RESULTADOS_R!$T$35*I5)+(RESULTADOS_R!$T$36*I4) -> -0.00022154022 | O8: =I8-N8 -> 0.00045350496 | Q8: ESTIMAÇÃO | R8: 2021/09/21 | S8: -0.051488272 | T8: =RESULTADOS_R!$T$37 -> -0.001944 | U8: =S8-T8 -> -0.049544272 | W8: ESTIMAÇÃO | X8: 2021/09/21 | Y8: -0.068014304 | Z8: =RESULTADOS_R!$T$38 -> -0.001799 | AA8: =Y8-Z8 -> -0.066215304 | AC8: ESTIMAÇÃO | AD8: 2021/09/21 | AE8: 0.0058618704 | AF8: 0.0055258182 | AG8: 0.00043905291 | AH8: -0.022110444 | AI8: -0.0064945764 | AJ8: =RESULTADOS_R!$T$39+(RESULTADOS_R!$T$40*AE7)+(RESULTADOS_R!$T$41*AE6)+(RESULTADOS_R!$T$42*AE5)+(RESULTADOS_R!$T$43*AE4) -> 0.00039667249 | AK8: =AE8-AJ8 -> 0.0054651979 | AM8: ESTIMAÇÃO | AN8: 2021/09/21 | AO8: 0.010130575 | AP8: -0.0066088171 | AQ8: -0.023720016 | AR8: -0.038058476 | AS8: -0.00058758107 | AT8: =RESULTADOS_R!$T$44+(RESULTADOS_R!$T$45*AO7)+(RESULTADOS_R!$T$46*AO6)+(RESULTADOS_R!$T$47*AO5)+(RESULTADOS_R!$T$48*AO4) -> -0.0046838863 | AU8: =AO8-AT8 -> 0.014814462 | AW8: ESTIMAÇÃO | AX8: 2021/09/21 | AY8: -0.00077220081 | AZ8: =RESULTADOS_R!$T$49 -> 0.0003559 | BA8: =AY8-AZ8 -> -0.0011281008
A9: ESTIMAÇÃO | B9: 2021/09/22 | C9: 0.0094631441 | D9: =RESULTADOS_R!$T$31 -> 0.0002891 | E9: =C9-D9 -> 0.0091740441 | G9: ESTIMAÇÃO | H9: 2021/09/22 | I9: -0.00058001278 | J9: 0.00023196474 | K9: 0.00023201856 | L9: -0.00023201856 | M9: -0.00034792694 | N9: =RESULTADOS_R!$T$32+(RESULTADOS_R!$T$33*I8)+(RESULTADOS_R!$T$34*I7)+(RESULTADOS_R!$T$35*I6)+(RESULTADOS_R!$T$36*I5) -> -0.00017075936 | O9: =I9-N9 -> -0.00040925341 | Q9: ESTIMAÇÃO | R9: 2021/09/22 | S9: 0.068399605 | T9: =RESULTADOS_R!$T$37 -> -0.001944 | U9: =S9-T9 -> 0.070343605 | W9: ESTIMAÇÃO | X9: 2021/09/22 | Y9: 0.10740227 | Z9: =RESULTADOS_R!$T$38 -> -0.001799 | AA9: =Y9-Z9 -> 0.10920127 | AC9: ESTIMAÇÃO | AD9: 2021/09/22 | AE9: -0.0035797405 | AF9: 0.0058618704 | AG9: 0.0055258182 | AH9: 0.00043905291 | AI9: -0.022110444 | AJ9: =RESULTADOS_R!$T$39+(RESULTADOS_R!$T$40*AE8)+(RESULTADOS_R!$T$41*AE7)+(RESULTADOS_R!$T$42*AE6)+(RESULTADOS_R!$T$43*AE5) -> -0.00094244514 | AK9: =AE9-AJ9 -> -0.0026372953 | AM9: ESTIMAÇÃO | AN9: 2021/09/22 | AO9: 0.0087725691 | AP9: 0.010130575 | AQ9: -0.0066088171 | AR9: -0.023720016 | AS9: -0.038058476 | AT9: =RESULTADOS_R!$T$44+(RESULTADOS_R!$T$45*AO8)+(RESULTADOS_R!$T$46*AO7)+(RESULTADOS_R!$T$47*AO6)+(RESULTADOS_R!$T$48*AO5) -> 0.0013494813 | AU9: =AO9-AT9 -> 0.0074230878 | AW9: ESTIMAÇÃO | AX9: 2021/09/22 | AY9: 0.0027642973 | AZ9: =RESULTADOS_R!$T$49 -> 0.0003559 | BA9: =AY9-AZ9 -> 0.0024083973
A10: ESTIMAÇÃO | B10: 2021/09/23 | C10: 0.012075311 | D10: =RESULTADOS_R!$T$31 -> 0.0002891 | E10: =C10-D10 -> 0.011786211 | G10: ESTIMAÇÃO | H10: 2021/09/23 | I10: -0.00058034939 | J10: -0.00058001278 | K10: 0.00023196474 | L10: 0.00023201856 | M10: -0.00023201856 | N10: =RESULTADOS_R!$T$32+(RESULTADOS_R!$T$33*I9)+(RESULTADOS_R!$T$34*I8)+(RESULTADOS_R!$T$35*I7)+(RESULTADOS_R!$T$36*I6) -> -0.00017354089 | O10: =I10-N10 -> -0.0004068085 | Q10: ESTIMAÇÃO | R10: 2021/09/23 | S10: 0.029856248 | T10: =RESULTADOS_R!$T$37 -> -0.001944 | U10: =S10-T10 -> 0.031800248 | W10: ESTIMAÇÃO | X10: 2021/09/23 | Y10: 0.02491734 | Z10: =RESULTADOS_R!$T$38 -> -0.001799 | AA10: =Y10-Z10 -> 0.02671634 | AC10: ESTIMAÇÃO | AD10: 2021/09/23 | AE10: -0.014437023 | AF10: -0.0035797405 | AG10: 0.0058618704 | AH10: 0.0055258182 | AI10: 0.00043905291 | AJ10: =RESULTADOS_R!$T$39+(RESULTADOS_R!$T$40*AE9)+(RESULTADOS_R!$T$41*AE8)+(RESULTADOS_R!$T$42*AE7)+(RESULTADOS_R!$T$43*AE6) -> -0.0010936799 | AK10: =AE10-AJ10 -> -0.013343343 | AM10: ESTIMAÇÃO | AN10: 2021/09/23 | AO10: -0.0080785972 | AP10: 0.0087725691 | AQ10: 0.010130575 | AR10: -0.0066088171 | AS10: -0.023720016 | AT10: =RESULTADOS_R!$T$44+(RESULTADOS_R!$T$45*AO9)+(RESULTADOS_R!$T$46*AO8)+(RESULTADOS_R!$T$47*AO7)+(RESULTADOS_R!$T$48*AO6) -> -0.00029639211 | AU10: =AO10-AT10 -> -0.0077822051 | AW10: ESTIMAÇÃO | AX10: 2021/09/23 | AY10: -0.0046006676 | AZ10: =RESULTADOS_R!$T$49 -> 0.0003559 | BA10: =AY10-AZ10 -> -0.0049565676
A11: ESTIMAÇÃO | B11: 2021/09/24 | C11: 0.0014599362 | D11: =RESULTADOS_R!$T$31 -> 0.0002891 | E11: =C11-D11 -> 0.0011708362 | G11: ESTIMAÇÃO | H11: 2021/09/24 | I11: -0.00034837137 | J11: -0.00058034939 | K11: -0.00058001278 | L11: 0.00023196474 | M11: 0.00023201856 | N11: =RESULTADOS_R!$T$32+(RESULTADOS_R!$T$33*I10)+(RESULTADOS_R!$T$34*I9)+(RESULTADOS_R!$T$35*I8)+(RESULTADOS_R!$T$36*I7) -> -0.00022540543 | O11: =I11-N11 -> -0.00012296594 | Q11: ESTIMAÇÃO | R11: 2021/09/24 | S11: -0.046862132 | T11: =RESULTADOS_R!$T$37 -> -0.001944 | U11: =S11-T11 -> -0.044918132 | W11: ESTIMAÇÃO | X11: 2021/09/24 | Y11: -0.073582524 | Z11: =RESULTADOS_R!$T$38 -> -0.001799 | AA11: =Y11-Z11 -> -0.071783524 | AC11: ESTIMAÇÃO | AD11: 2021/09/24 | AE11: 0.0041747497 | AF11: -0.014437023 | AG11: -0.0035797405 | AH11: 0.0058618704 | AI11: 0.0055258182 | AJ11: =RESULTADOS_R!$T$39+(RESULTADOS_R!$T$40*AE10)+(RESULTADOS_R!$T$41*AE9)+(RESULTADOS_R!$T$42*AE8)+(RESULTADOS_R!$T$43*AE7) -> 1.4280466e-05 | AK11: =AE11-AJ11 -> 0.0041604693 | AM11: ESTIMAÇÃO | AN11: 2021/09/24 | AO11: -0.0032114339 | AP11: -0.0080785972 | AQ11: 0.0087725691 | AR11: 0.010130575 | AS11: -0.0066088171 | AT11: =RESULTADOS_R!$T$44+(RESULTADOS_R!$T$45*AO10)+(RESULTADOS_R!$T$46*AO9)+(RESULTADOS_R!$T$47*AO8)+(RESULTADOS_R!$T$48*AO7) -> -0.0021483836 | AU11: =AO11-AT11 -> -0.0010630503 | AW11: ESTIMAÇÃO | AX11: 2021/09/24 | AY11: 0.0031551861 | AZ11: =RESULTADOS_R!$T$49 -> 0.0003559 | BA11: =AY11-AZ11 -> 0.0027992861
A12: ESTIMAÇÃO | B12: 2021/09/27 | C12: -0.0027869571 | D12: =RESULTADOS_R!$T$31 -> 0.0002891 | E12: =C12-D12 -> -0.0030760571 | G12: ESTIMAÇÃO | H12: 2021/09/27 | I12: -0.00011615076 | J12: -0.00034837137 | K12: -0.00058034939 | L12: -0.00058001278 | M12: 0.00023196474 | N12: =RESULTADOS_R!$T$32+(RESULTADOS_R!$T$33*I11)+(RESULTADOS_R!$T$34*I10)+(RESULTADOS_R!$T$35*I9)+(RESULTADOS_R!$T$36*I8) -> -0.00018612214 | O12: =I12-N12 -> 6.9971373e-05 | Q12: ESTIMAÇÃO | R12: 2021/09/27 | S12: -0.01419986 | T12: =RESULTADOS_R!$T$37 -> -0.001944 | U12: =S12-T12 -> -0.01225586 | W12: ESTIMAÇÃO | X12: 2021/09/27 | Y12: 0.0008420261 | Z12: =RESULTADOS_R!$T$38 -> -0.001799 | AA12: =Y12-Z12 -> 0.0026410261 | AC12: ESTIMAÇÃO | AD12: 2021/09/27 | AE12: -5.7147592e-06 | AF12: 0.0041747497 | AG12: -0.014437023 | AH12: -0.0035797405 | AI12: 0.0058618704 | AJ12: =RESULTADOS_R!$T$39+(RESULTADOS_R!$T$40*AE11)+(RESULTADOS_R!$T$41*AE10)+(RESULTADOS_R!$T$42*AE9)+(RESULTADOS_R!$T$43*AE8) -> 0.0035829544 | AK12: =AE12-AJ12 -> -0.0035886691 | AM12: ESTIMAÇÃO | AN12: 2021/09/27 | AO12: 0.010429474 | AP12: -0.0032114339 | AQ12: -0.0080785972 | AR12: 0.0087725691 | AS12: 0.010130575 | AT12: =RESULTADOS_R!$T$44+(RESULTADOS_R!$T$45*AO11)+(RESULTADOS_R!$T$46*AO10)+(RESULTADOS_R!$T$47*AO9)+(RESULTADOS_R!$T$48*AO8) -> 0.0026663272 | AU12: =AO12-AT12 -> 0.0077631472 | AW12: ESTIMAÇÃO | AX12: 2021/09/27 | AY12: 0.00059986076 | AZ12: =RESULTADOS_R!$T$49 -> 0.0003559 | BA12: =AY12-AZ12 -> 0.00024396076
A13: ESTIMAÇÃO | B13: 2021/09/28 | C13: -0.020578963 | D13: =RESULTADOS_R!$T$31 -> 0.0002891 | E13: =C13-D13 -> -0.020868063 | G13: ESTIMAÇÃO | H13: 2021/09/28 | I13: 0.00011615076 | J13: -0.00011615076 | K13: -0.00034837137 | L13: -0.00058034939 | M13: -0.00058001278 | N13: =RESULTADOS_R!$T$32+(RESULTADOS_R!$T$33*I12)+(RESULTADOS_R!$T$34*I11)+(RESULTADOS_R!$T$35*I10)+(RESULTADOS_R!$T$36*I9) -> 5.1684405e-05 | O13: =I13-N13 -> 6.4466359e-05 | Q13: ESTIMAÇÃO | R13: 2021/09/28 | S13: -0.028852324 | T13: =RESULTADOS_R!$T$37 -> -0.001944 | U13: =S13-T13 -> -0.026908324 | W13: ESTIMAÇÃO | X13: 2021/09/28 | Y13: -0.044191979 | Z13: =RESULTADOS_R!$T$38 -> -0.001799 | AA13: =Y13-Z13 -> -0.042392979 | AC13: ESTIMAÇÃO | AD13: 2021/09/28 | AE13: -0.0092837531 | AF13: -5.7147592e-06 | AG13: 0.0041747497 | AH13: -0.014437023 | AI13: -0.0035797405 | AJ13: =RESULTADOS_R!$T$39+(RESULTADOS_R!$T$40*AE12)+(RESULTADOS_R!$T$41*AE11)+(RESULTADOS_R!$T$42*AE10)+(RESULTADOS_R!$T$43*AE9) -> -0.00066005698 | AK13: =AE13-AJ13 -> -0.0086236961 | AM13: ESTIMAÇÃO | AN13: 2021/09/28 | AO13: -0.0096267629 | AP13: 0.010429474 | AQ13: -0.0032114339 | AR13: -0.0080785972 | AS13: 0.0087725691 | AT13: =RESULTADOS_R!$T$44+(RESULTADOS_R!$T$45*AO12)+(RESULTADOS_R!$T$46*AO11)+(RESULTADOS_R!$T$47*AO10)+(RESULTADOS_R!$T$48*AO9) -> 0.0016995188 | AU13: =AO13-AT13 -> -0.011326282 | AW13: ESTIMAÇÃO | AX13: 2021/09/28 | AY13: 0.0040930011 | AZ13: =RESULTADOS_R!$T$49 -> 0.0003559 | BA13: =AY13-AZ13 -> 0.0037371011
A14: ESTIMAÇÃO | B14: 2021/09/29 | C14: 0.0015840042 | D14: =RESULTADOS_R!$T$31 -> 0.0002891 | E14: =C14-D14 -> 0.0012949042 | G14: ESTIMAÇÃO | H14: 2021/09/29 | I14: 0.00034837137 | J14: 0.00011615076 | K14: -0.00011615076 | L14: -0.00034837137 | M14: -0.00058034939 | N14: =RESULTADOS_R!$T$32+(RESULTADOS_R!$T$33*I13)+(RESULTADOS_R!$T$34*I12)+(RESULTADOS_R!$T$35*I11)+(RESULTADOS_R!$T$36*I10) -> -1.9103433e-05 | O14: =I14-N14 -> 0.0003674748 | Q14: ESTIMAÇÃO | R14: 2021/09/29 | S14: 0.012828888 | T14: =RESULTADOS_R!$T$37 -> -0.001944 | U14: =S14-T14 -> 0.014772888 | W14: ESTIMAÇÃO | X14: 2021/09/29 | Y14: 0.016199318 | Z14: =RESULTADOS_R!$T$38 -> -0.001799 | AA14: =Y14-Z14 -> 0.017998318 | AC14: ESTIMAÇÃO | AD14: 2021/09/29 | AE14: -0.0043759951 | AF14: -0.0092837531 | AG14: -5.7147592e-06 | AH14: 0.0041747497 | AI14: -0.014437023 | AJ14: =RESULTADOS_R!$T$39+(RESULTADOS_R!$T$40*AE13)+(RESULTADOS_R!$T$41*AE12)+(RESULTADOS_R!$T$42*AE11)+(RESULTADOS_R!$T$43*AE10) -> -0.00084843983 | AK14: =AE14-AJ14 -> -0.0035275553 | AM14: ESTIMAÇÃO | AN14: 2021/09/29 | AO14: -0.041894279 | AP14: -0.0096267629 | AQ14: 0.010429474 | AR14: -0.0032114339 | AS14: -0.0080785972 | AT14: =RESULTADOS_R!$T$44+(RESULTADOS_R!$T$45*AO13)+(RESULTADOS_R!$T$46*AO12)+(RESULTADOS_R!$T$47*AO11)+(RESULTADOS_R!$T$48*AO10) -> -0.0061495691 | AU14: =AO14-AT14 -> -0.03574471 | AW14: ESTIMAÇÃO | AX14: 2021/09/29 | AY14: 0.0060817608 | AZ14: =RESULTADOS_R!$T$49 -> 0.0003559 | BA14: =AY14-AZ14 -> 0.0057258608
A15: ESTIMAÇÃO | B15: 2021/09/30 | C15: -0.011999682 | D15: =RESULTADOS_R!$T$31 -> 0.0002891 | E15: =C15-D15 -> -0.012288782 | G15: ESTIMAÇÃO | H15: 2021/09/30 | I15: 0.00023218017 | J15: 0.00034837137 | K15: 0.00011615076 | L15: -0.00011615076 | M15: -0.00034837137 | N15: =RESULTADOS_R!$T$32+(RESULTADOS_R!$T$33*I14)+(RESULTADOS_R!$T$34*I13)+(RESULTADOS_R!$T$35*I12)+(RESULTADOS_R!$T$36*I11) -> -0.0001733063 | O15: =I15-N15 -> 0.00040548648 | Q15: ESTIMAÇÃO | R15: 2021/09/30 | S15: 0.05218278 | T15: =RESULTADOS_R!$T$37 -> -0.001944 | U15: =S15-T15 -> 0.05412678 | W15: ESTIMAÇÃO | X15: 2021/09/30 | Y15: 0.050750492 | Z15: =RESULTADOS_R!$T$38 -> -0.001799 | AA15: =Y15-Z15 -> 0.052549492 | AC15: ESTIMAÇÃO | AD15: 2021/09/30 | AE15: 0.017543957 | AF15: -0.0043759951 | AG15: -0.0092837531 | AH15: -5.7147592e-06 | AI15: 0.0041747497 | AJ15: =RESULTADOS_R!$T$39+(RESULTADOS_R!$T$40*AE14)+(RESULTADOS_R!$T$41*AE13)+(RESULTADOS_R!$T$42*AE12)+(RESULTADOS_R!$T$43*AE11) -> 0.0018647279 | AK15: =AE15-AJ15 -> 0.015679229 | AM15: ESTIMAÇÃO | AN15: 2021/09/30 | AO15: 0.031453479 | AP15: -0.041894279 | AQ15: -0.0096267629 | AR15: 0.010429474 | AS15: -0.0032114339 | AT15: =RESULTADOS_R!$T$44+(RESULTADOS_R!$T$45*AO14)+(RESULTADOS_R!$T$46*AO13)+(RESULTADOS_R!$T$47*AO12)+(RESULTADOS_R!$T$48*AO11) -> -0.0078562806 | AU15: =AO15-AT15 -> 0.039309759 | AW15: ESTIMAÇÃO | AX15: 2021/09/30 | AY15: -0.0011454755 | AZ15: =RESULTADOS_R!$T$49 -> 0.0003559 | BA15: =AY15-AZ15 -> -0.0015013755
A16: ESTIMAÇÃO | B16: 2021/10/01 | C16: 0.011426058 | D16: =RESULTADOS_R!$T$31 -> 0.0002891 | E16: =C16-D16 -> 0.011136958 | G16: ESTIMAÇÃO | H16: 2021/10/01 | I16: 0.00034816921 | J16: 0.00023218017 | K16: 0.00034837137 | L16: 0.00011615076 | M16: -0.00011615076 | N16: =RESULTADOS_R!$T$32+(RESULTADOS_R!$T$33*I15)+(RESULTADOS_R!$T$34*I14)+(RESULTADOS_R!$T$35*I13)+(RESULTADOS_R!$T$36*I12) -> -0.00029619099 | O16: =I16-N16 -> 0.00064436021 | Q16: ESTIMAÇÃO | R16: 2021/10/01 | S16: 0.09420839 | T16: =RESULTADOS_R!$T$37 -> -0.001944 | U16: =S16-T16 -> 0.09615239 | W16: ESTIMAÇÃO | X16: 2021/10/01 | Y16: 0.097025662 | Z16: =RESULTADOS_R!$T$38 -> -0.001799 | AA16: =Y16-Z16 -> 0.098824662 | AC16: ESTIMAÇÃO | AD16: 2021/10/01 | AE16: 0.0021040548 | AF16: 0.017543957 | AG16: -0.0043759951 | AH16: -0.0092837531 | AI16: -5.7147592e-06 | AJ16: =RESULTADOS_R!$T$39+(RESULTADOS_R!$T$40*AE15)+(RESULTADOS_R!$T$41*AE14)+(RESULTADOS_R!$T$42*AE13)+(RESULTADOS_R!$T$43*AE12) -> 0.002516509 | AK16: =AE16-AJ16 -> -0.00041245423 | AM16: ESTIMAÇÃO | AN16: 2021/10/01 | AO16: 0.014311514 | AP16: 0.031453479 | AQ16: -0.041894279 | AR16: -0.0096267629 | AS16: 0.010429474 | AT16: =RESULTADOS_R!$T$44+(RESULTADOS_R!$T$45*AO15)+(RESULTADOS_R!$T$46*AO14)+(RESULTADOS_R!$T$47*AO13)+(RESULTADOS_R!$T$48*AO12) -> 0.018176567 | AU16: =AO16-AT16 -> -0.0038650527 | AW16: ESTIMAÇÃO | AX16: 2021/10/01 | AY16: -0.0020715488 | AZ16: =RESULTADOS_R!$T$49 -> 0.0003559 | BA16: =AY16-AZ16 -> -0.0024274488
A17: ESTIMAÇÃO | B17: 2021/10/04 | C17: -0.013052452 | D17: =RESULTADOS_R!$T$31 -> 0.0002891 | E17: =C17-D17 -> -0.013341552 | G17: ESTIMAÇÃO | H17: 2021/10/04 | I17: -0.00046425256 | J17: 0.00034816921 | K17: 0.00023218017 | L17: 0.00034837137 | M17: 0.00011615076 | N17: =RESULTADOS_R!$T$32+(RESULTADOS_R!$T$33*I16)+(RESULTADOS_R!$T$34*I15)+(RESULTADOS_R!$T$35*I14)+(RESULTADOS_R!$T$36*I13) -> -0.00039081774 | O17: =I17-N17 -> -7.343482e-05 | Q17: ESTIMAÇÃO | R17: 2021/10/04 | S17: 0.020487432 | T17: =RESULTADOS_R!$T$37 -> -0.001944 | U17: =S17-T17 -> 0.022431432 | W17: ESTIMAÇÃO | X17: 2021/10/04 | Y17: 0.021704622 | Z17: =RESULTADOS_R!$T$38 -> -0.001799 | AA17: =Y17-Z17 -> 0.023503622 | AC17: ESTIMAÇÃO | AD17: 2021/10/04 | AE17: 0.0051843385 | AF17: 0.0021040548 | AG17: 0.017543957 | AH17: -0.0043759951 | AI17: -0.0092837531 | AJ17: =RESULTADOS_R!$T$39+(RESULTADOS_R!$T$40*AE16)+(RESULTADOS_R!$T$41*AE15)+(RESULTADOS_R!$T$42*AE14)+(RESULTADOS_R!$T$43*AE13) -> -0.0032125459 | AK17: =AE17-AJ17 -> 0.0083968845 | AM17: ESTIMAÇÃO | AN17: 2021/10/04 | AO17: 0.006157734 | AP17: 0.014311514 | AQ17: 0.031453479 | AR17: -0.041894279 | AS17: -0.0096267629 | AT17: =RESULTADOS_R!$T$44+(RESULTADOS_R!$T$45*AO16)+(RESULTADOS_R!$T$46*AO15)+(RESULTADOS_R!$T$47*AO14)+(RESULTADOS_R!$T$48*AO13) -> -0.013395344 | AU17: =AO17-AT17 -> 0.019553078 | AW17: ESTIMAÇÃO | AX17: 2021/10/04 | AY17: -0.0027580937 | AZ17: =RESULTADOS_R!$T$49 -> 0.0003559 | BA17: =AY17-AZ17 -> -0.0031139937
... A126: AJUSTE | B126: 2022/03/10 | C126: -0.0043010819 | D126: =RESULTADOS_R!$T$31 -> 0.0002891 | E126: =C126-D126 -> -0.0045901819 | G126: AJUSTE | H126: 2022/03/10 | I126: -0.00083100854 | J126: -0.00059315501 | K126: -0.0013037039 | L126: -0.0013020065 | M126: 0.0010651519 | N126: =RESULTADOS_R!$T$32+(RESULTADOS_R!$T$33*I125)+(RESULTADOS_R!$T$34*I124)+(RESULTADOS_R!$T$35*I123)+(RESULTADOS_R!$T$36*I122) -> -0.00030752858 | O126: =I126-N126 -> -0.00052347996 | Q126: AJUSTE | R126: 2022/03/10 | S126: -0.0625469 | T126: =RESULTADOS_R!$T$37 -> -0.001944 | U126: =S126-T126 -> -0.0606029 | W126: AJUSTE | X126: 2022/03/10 | Y126: -0.045620064 | Z126: =RESULTADOS_R!$T$38 -> -0.001799 | AA126: =Y126-Z126 -> -0.043821064 | AC126: AJUSTE | AD126: 2022/03/10 | AE126: 0.0021919329 | AF126: -0.03013161 | AG126: 0.026812979 | AH126: 0.014955303 | AI126: 0.017030583 | AJ126: =RESULTADOS_R!$T$39+(RESULTADOS_R!$T$40*AE125)+(RESULTADOS_R!$T$41*AE124)+(RESULTADOS_R!$T$42*AE123)+(RESULTADOS_R!$T$43*AE122) -> -0.0067606037 | AK126: =AE126-AJ126 -> 0.0089525366 | AM126: AJUSTE | AN126: 2022/03/10 | AO126: 0.0057658488 | AP126: -0.02512397 | AQ126: 0.028015512 | AR126: -0.00029615428 | AS126: 0.019915623 | AT126: =RESULTADOS_R!$T$44+(RESULTADOS_R!$T$45*AO125)+(RESULTADOS_R!$T$46*AO124)+(RESULTADOS_R!$T$47*AO123)+(RESULTADOS_R!$T$48*AO122) -> -0.016519734 | AU126: =AO126-AT126 -> 0.022285582 | AW126: AJUSTE | AX126: 2022/03/10 | AY126: 0.0054867169 | AZ126: =RESULTADOS_R!$T$49 -> 0.0003559 | BA126: =AY126-AZ126 -> 0.0051308169

Sheet RESULTADOS_R
B2: Teste de Estacionariedade | Q2: EVENTO 1
B3: ATIVOS | C3: EVENTO 1 | E3: EVENTO 2 | Q3: ATIVOS | R3: Correspondente a | S3: Variáveis | T3: Coeficiente | U3: Std. Error | V3: t value | W3: p-value
C4: ADF | D4: KPSS | E4: ADF | F4: KPSS | Q4: SPX | R4: intercept | S4: b0 | T4: 0.00209898 | U4: 0.00069425 | V4: 3.0234 | W4: 0.003247
B5: SPX | C5: 0.01 | D5: 0.1 | E5: 0.01 | F5: 0.1 | R5: lag1 | S5: b1 | T5: -0.10683371 | U5: 0.08195027 | V5: -1.3036 | W5: 0.195645
B6: SHY | C6: 0.01 | D6: 0.1 | E6: 0.01 | F6: 0.1 | H6: MODELO - TESTES RESÍDUOS | R6: lag2 | S6: b2 | T6: -0.16468309 | U6: 0.09066602 | V6: -1.8164 | W6: 0.072606
B7: BTC | C7: 0.01 | D7: 0.1 | E7: 0.01 | F7: 0.06722 | H7: ATIVOS | I7: Testes | J7: Evento 1 | K7: Evento 2 | R7: lag3 | S7: b3 | T7: -0.2618902 | U7: 0.05664099 | V7: -4.6237 | W7: 1.241e-05
B8: ETH | C8: 0.0171 | D8: 0.06445 | E8: 0.01 | F8: 0.1 | H8: SPX | I8: Shapiro-Wilk | J8: 0.04434 | K8: 0.5517 | R8: lag4 | S8: b4 | T8: 0.19271172 | U8: 0.10928498 | V8: 1.7634 | W8: 0.081192
B9: OURO | C9: 0.01 | D9: 0.0881 | E9: 0.01 | F9: 0.1 | I9: Breusch-Pagan | J9: 0.01376 | K9: * | Q9: SHY | R9: intercept | S9: b0 | T9: -8.056e-06 | U9: 6.9721e-05 | V9: -0.116 | W9: 0.9083
B10: PRATA | C10: 0.01696 | D10: 0.1 | E10: 0.01913 | F10: 0.1 | I10: Box-Ljung (Lag-5) | J10: 0.9075 | K10: 0.4716 | R10: lag1 | S10: b1 | T10: -0.12711554 | U10: 0.09940385 | V10: -1.279 | W10: 0.2043
B11: DXY | C11: 0.01 | D11: 0.05186 | E11: 0.01 | F11: 0.1 | H11: SHY | I11: Shapiro-Wilk | J11: 0.02185 | K11: 0.1181 | R11: lag2 | S11: b2 | T11: 0.031174167 | U11: 0.098234548 | V11: 0.317 | W11: 0.7517
I12: Breusch-Pagan | J12: 0.3842 | K12: 0.8848 | R12: lag3 | S12: b3 | T12: -0.17300067 | U12: 0.097300202 | V12: -1.778 | W12: 0.0788
I13: Box-Ljung (Lag-5) | J13: 0.9045 | K13: 0.9728 | R13: lag4 | S13: b4 | T13: 0.037518327 | U13: 0.098551972 | V13: 0.381 | W13: 0.7043
B14: AIC | H14: BTC | I14: Shapiro-Wilk | J14: 0.0002539 | K14: 0.5006 | R14: lag5 | S14: b5 | T14: -0.097260857 | U14: 0.097834945 | V14: -0.994 | W14: 0.3229
B15: ATIVOS | C15: EV1 | D15: EV2 | I15: Breusch-Pagan | J15: 0.1532 | K15: * | Q15: BTC | R15: intercept | S15: b0 | T15: 0.001639 | U15: 0.003166 | V15: 0.518 | W15: 0.6059
B16: SPX | C16: 4 | D16: 0 | I16: Box-Ljung (Lag-5) | J16: 0.925 | K16: 0.6892 | R16: lag1 | S16: b1 | T16: 0.235657 | U16: 0.100069 | V16: 2.355 | W16: 0.0206
B17: SHY | C17: 5 | D17: 4 | H17: ETH | I17: Shapiro-Wilk | J17: 0.0007024 | K17: 0.2319 | R17: lag2 | S17: b2 | T17: -0.224513 | U17: 0.101401 | V17: -2.214 | W17: 0.0292
B18: BTC | C18: 2 | D18: 0 | I18: Breusch-Pagan | J18: * | K18: * | Q18: ETH | R18: intercept | S18: b0 | T18: 0.004364 | U18: 0.003954 | V18: 1.104 | W18: 0.272
B19: ETH | C19: 0 | D19: 0 | I19: Box-Ljung (Lag-5) | J19: 0.7175 | K19: 0.6855 | Q19: OURO | R19: intercept | S19: b0 | T19: 0.0007639 | U19: 0.0006381 | V19: 1.197 | W19: 0.2343
B20: OURO | C20: 4 | D20: 4 | H20: OURO | I20: Shapiro-Wilk | J20: 0.00562 | K20: 0.9621 | R20: lag1 | S20: b1 | T20: 0.075117 | U20: 0.1026261 | V20: 0.732 | W20: 0.4661
B21: PRATA | C21: 2 | D21: 4 | I21: Breusch-Pagan | J21: 0.7161 | K21: 0.8144 | R21: lag2 | S21: b2 | T21: 0.0456296 | U21: 0.100526 | V21: 0.454 | W21: 0.651
B22: DXY | C22: 1 | D22: 0 | I22: Box-Ljung (Lag-5) | J22: 0.9955 | K22: 0.9951 | R22: lag3 | S22: b3 | T22: -0.1900997 | U22: 0.097771 | V22: -1.944 | W22: 0.0549
H23: PRATA | I23: Shapiro-Wilk | J23: 0.004276 | K23: 0.7386 | R23: lag4 | S23: b4 | T23: 0.0936973 | U23: 0.0998201 | V23: 0.939 | W23: 0.3504
I24: Breusch-Pagan | J24: 0.554 | K24: 0.2486 | Q24: PRATA | R24: intercept | S24: b0 | T24: 0.0008288 | U24: 0.0011159 | V24: 0.743 | W24: 0.459
